2019-01-08 13:07:46+0800 [-] Log opened.
2019-01-08 13:07:47+0800 [-] EchoFactory starting on 8001
2019-01-08 13:07:47+0800 [-] Starting factory <__main__.EchoFactory object at 0x0481EAB0>
2019-01-08 13:07:47+0800 [-] Listening....
2019-01-08 13:07:47+0800 [-] 
2019-01-08 13:09:37+0800 [-] BC9EEB51694F60AA7AA590191A79AC4F
2019-01-08 13:09:37+0800 [-] ((None, 'A1', 7), ('khb_product_1', 'A1', 8))
2019-01-08 13:09:37+0800 [-] model_nameNone
2019-01-08 13:09:37+0800 [-] {'model_name': None, 'data_type': {'A1': {'01': 'Float'}}, 'typemappointname': {'A1': {'01': '电流_1'}}}
2019-01-08 13:09:37+0800 [-] None
2019-01-08 13:09:37+0800 [-] Unhandled error in Deferred:
2019-01-08 13:09:37+0800 [-] Unhandled Error
	Traceback (most recent call last):
	  File "C:\Python\Python36-32\lib\site-packages\twisted\internet\base.py", line 1252, in mainLoop
	    self.runUntilCurrent()
	  File "C:\Python\Python36-32\lib\site-packages\twisted\internet\base.py", line 851, in runUntilCurrent
	    f(*a, **kw)
	  File "C:\Python\Python36-32\lib\site-packages\twisted\internet\defer.py", line 459, in callback
	    self._startRunCallbacks(result)
	  File "C:\Python\Python36-32\lib\site-packages\twisted\internet\defer.py", line 567, in _startRunCallbacks
	    self._runCallbacks()
	--- <exception caught here> ---
	  File "C:\Python\Python36-32\lib\site-packages\twisted\internet\defer.py", line 653, in _runCallbacks
	    current.result = callback(current.result, *args, **kw)
	  File "E:\Python-L\Plat-1\Plat\Iotserver\server.py", line 194, in get_model_struct
	    defer_instancs = AutoDelect(self.model_struct,datastr,sqlconnect)
	  File "E:\Python-L\Plat-1\Plat\Iotserver\AutodelectProtocol\Autodelectprotoctol.py", line 33, in AutoDelect
	    table_name = model_struct['model_name']+'_'+'Data'
	builtins.TypeError: unsupported operand type(s) for +: 'NoneType' and 'str'
	
2019-01-08 13:09:39+0800 [-] BC9EEB51694F60AA7AA590191A79AC4F
2019-01-08 13:09:39+0800 [-] ((None, 'A1', 7), ('khb_product_1', 'A1', 8))
2019-01-08 13:09:39+0800 [-] model_nameNone
2019-01-08 13:09:39+0800 [-] {'model_name': None, 'data_type': {'A1': {'01': 'Float'}}, 'typemappointname': {'A1': {'01': '电流_1'}}}
2019-01-08 13:09:39+0800 [-] None
2019-01-08 13:09:39+0800 [-] Unhandled error in Deferred:
2019-01-08 13:09:39+0800 [-] Unhandled Error
	Traceback (most recent call last):
	  File "C:\Python\Python36-32\lib\site-packages\twisted\internet\base.py", line 1252, in mainLoop
	    self.runUntilCurrent()
	  File "C:\Python\Python36-32\lib\site-packages\twisted\internet\base.py", line 851, in runUntilCurrent
	    f(*a, **kw)
	  File "C:\Python\Python36-32\lib\site-packages\twisted\internet\defer.py", line 459, in callback
	    self._startRunCallbacks(result)
	  File "C:\Python\Python36-32\lib\site-packages\twisted\internet\defer.py", line 567, in _startRunCallbacks
	    self._runCallbacks()
	--- <exception caught here> ---
	  File "C:\Python\Python36-32\lib\site-packages\twisted\internet\defer.py", line 653, in _runCallbacks
	    current.result = callback(current.result, *args, **kw)
	  File "E:\Python-L\Plat-1\Plat\Iotserver\server.py", line 194, in get_model_struct
	    defer_instancs = AutoDelect(self.model_struct,datastr,sqlconnect)
	  File "E:\Python-L\Plat-1\Plat\Iotserver\AutodelectProtocol\Autodelectprotoctol.py", line 33, in AutoDelect
	    table_name = model_struct['model_name']+'_'+'Data'
	builtins.TypeError: unsupported operand type(s) for +: 'NoneType' and 'str'
	
2019-01-08 13:17:51+0800 [-] Log opened.
2019-01-08 13:17:51+0800 [-] EchoFactory starting on 8001
2019-01-08 13:17:51+0800 [-] Starting factory <__main__.EchoFactory object at 0x04A2CAF0>
2019-01-08 13:17:51+0800 [-] Listening....
2019-01-08 13:17:51+0800 [-] 
2019-01-08 13:17:59+0800 [-] BC9EEB51694F60AA7AA590191A79AC4F
2019-01-08 13:18:00+0800 [-] ((None, 'A1', 7), ('khb_product_1', 'A1', 8))
2019-01-08 13:18:00+0800 [-] {'model_name': 'khb_product_1', 'data_type': {'A1': {'01': 'Float'}}, 'typemappointname': {'A1': {'01': '电流_1'}}}
2019-01-08 13:18:00+0800 [-] khb_product_1
2019-01-08 13:18:00+0800 [-] AutoDelect error:[Failure instance: Traceback: <class 'KeyError'>: '03'
	C:\Python\Python36-32\lib\site-packages\twisted\internet\defer.py:567:_startRunCallbacks
	C:\Python\Python36-32\lib\site-packages\twisted\internet\defer.py:653:_runCallbacks
	E:\Python-L\Plat-1\Plat\Iotserver\server.py:195:get_model_struct
	E:\Python-L\Plat-1\Plat\Iotserver\AutodelectProtocol\Autodelectprotoctol.py:47:AutoDelect
	--- <exception caught here> ---
	E:\Python-L\Plat-1\Plat\Iotserver\AutodelectProtocol\Autodelectprotoctol.py:41:AutoDelect
	]
2019-01-08 13:18:00+0800 [-] BC9EEB51694F60AA7AA590191A79AC4F
2019-01-08 13:18:00+0800 [-] khb_product_1
2019-01-08 13:18:00+0800 [Echo,0,192.168.0.110] AutoDelect error:[Failure instance: Traceback: <class 'KeyError'>: '03'
	C:\Python\Python36-32\lib\site-packages\twisted\internet\iocpreactor\tcp.py:75:dataReceived
	E:\Python-L\Plat-1\Plat\Iotserver\server.py:67:dataReceived
	E:\Python-L\Plat-1\Plat\Iotserver\server.py:89:datahanlder
	E:\Python-L\Plat-1\Plat\Iotserver\AutodelectProtocol\Autodelectprotoctol.py:47:AutoDelect
	--- <exception caught here> ---
	E:\Python-L\Plat-1\Plat\Iotserver\AutodelectProtocol\Autodelectprotoctol.py:41:AutoDelect
	]
2019-01-08 13:20:00+0800 [-] info:BC9EEB51694F60AA7AA590191A79AC4F timeout
2019-01-08 13:20:00+0800 [-] info:BC9EEB51694F60AA7AA590191A79AC4F disconnected
2019-01-08 13:20:44+0800 [-] Log opened.
2019-01-08 13:20:44+0800 [-] EchoFactory starting on 8001
2019-01-08 13:20:44+0800 [-] Starting factory <__main__.EchoFactory object at 0x03E9EAF0>
2019-01-08 13:20:44+0800 [-] Listening....
2019-01-08 13:20:44+0800 [-] 
2019-01-08 13:20:48+0800 [-] BC9EEB51694F60AA7AA590191A79AC4F
2019-01-08 13:20:48+0800 [-] ((None, 'A1', 7), ('khb_product_1', 'A1', 8))
2019-01-08 13:20:48+0800 [-] {'model_name': 'khb_product_1', 'data_type': {'A1': {'01': 'Float'}}, 'typemappointname': {'A1': {'01': '电流_1'}}}
2019-01-08 13:20:48+0800 [-] 0304BF9C28F604040000000A
2019-01-08 13:20:48+0800 [-] AutoDelect error:[Failure instance: Traceback: <class 'KeyError'>: '03'
	C:\Python\Python36-32\lib\site-packages\twisted\internet\defer.py:567:_startRunCallbacks
	C:\Python\Python36-32\lib\site-packages\twisted\internet\defer.py:653:_runCallbacks
	E:\Python-L\Plat-1\Plat\Iotserver\server.py:195:get_model_struct
	E:\Python-L\Plat-1\Plat\Iotserver\AutodelectProtocol\Autodelectprotoctol.py:47:AutoDelect
	--- <exception caught here> ---
	E:\Python-L\Plat-1\Plat\Iotserver\AutodelectProtocol\Autodelectprotoctol.py:41:AutoDelect
	]
2019-01-08 13:22:48+0800 [-] info:BC9EEB51694F60AA7AA590191A79AC4F timeout
2019-01-08 13:22:48+0800 [-] info:BC9EEB51694F60AA7AA590191A79AC4F disconnected
2019-01-08 13:25:56+0800 [-] Log opened.
2019-01-08 13:25:56+0800 [-] EchoFactory starting on 8001
2019-01-08 13:25:56+0800 [-] Starting factory <__main__.EchoFactory object at 0x0435DAF0>
2019-01-08 13:25:56+0800 [-] Listening....
2019-01-08 13:25:56+0800 [-] 
2019-01-08 13:26:02+0800 [-] BC9EEB51694F60AA7AA590191A79AC4F
2019-01-08 13:26:02+0800 [-] {'model_name': 'khb_product_1', 'data_type': {'A1': ''}, 'typemappointname': {}}
2019-01-08 13:26:03+0800 [-] {'model_name': 'khb_product_1', 'data_type': {'A1': {'01': 'Float'}}, 'typemappointname': {'A1': {'01': '电流_1'}}}
2019-01-08 13:26:03+0800 [-] 0304BF9C28F604040000000A
2019-01-08 13:26:03+0800 [-] AutoDelect error:[Failure instance: Traceback: <class 'KeyError'>: '03'
	C:\Python\Python36-32\lib\site-packages\twisted\internet\defer.py:567:_startRunCallbacks
	C:\Python\Python36-32\lib\site-packages\twisted\internet\defer.py:653:_runCallbacks
	E:\Python-L\Plat-1\Plat\Iotserver\server.py:194:get_model_struct
	E:\Python-L\Plat-1\Plat\Iotserver\AutodelectProtocol\Autodelectprotoctol.py:47:AutoDelect
	--- <exception caught here> ---
	E:\Python-L\Plat-1\Plat\Iotserver\AutodelectProtocol\Autodelectprotoctol.py:41:AutoDelect
	]
2019-01-08 13:28:02+0800 [-] info:BC9EEB51694F60AA7AA590191A79AC4F timeout
2019-01-08 13:28:02+0800 [-] info:BC9EEB51694F60AA7AA590191A79AC4F disconnected
2019-01-08 13:30:33+0800 [-] Log opened.
2019-01-08 13:30:33+0800 [-] EchoFactory starting on 8001
2019-01-08 13:30:33+0800 [-] Starting factory <__main__.EchoFactory object at 0x03B1EAF0>
2019-01-08 13:30:33+0800 [-] Listening....
2019-01-08 13:30:33+0800 [-] 
2019-01-08 13:30:44+0800 [-] BC9EEB51694F60AA7AA590191A79AC4F
2019-01-08 13:30:44+0800 [-] {'model_name': 'khb_product_1', 'data_type': {'A1': ''}, 'typemappointname': {}}
2019-01-08 13:30:44+0800 [-] [(('01', 'Float', '电流_1'),), (('04', 'UInt', 'temp_1'), ('03', 'Float', 'current_1'))]
2019-01-08 13:30:44+0800 [-] {'model_name': 'khb_product_1', 'data_type': {'A1': {'01': 'Float'}}, 'typemappointname': {'A1': {'01': '电流_1'}}}
2019-01-08 13:30:44+0800 [-] 0304BF9C28F604040000000A
2019-01-08 13:30:44+0800 [-] AutoDelect error:[Failure instance: Traceback: <class 'KeyError'>: '03'
	C:\Python\Python36-32\lib\site-packages\twisted\internet\defer.py:567:_startRunCallbacks
	C:\Python\Python36-32\lib\site-packages\twisted\internet\defer.py:653:_runCallbacks
	E:\Python-L\Plat-1\Plat\Iotserver\server.py:195:get_model_struct
	E:\Python-L\Plat-1\Plat\Iotserver\AutodelectProtocol\Autodelectprotoctol.py:47:AutoDelect
	--- <exception caught here> ---
	E:\Python-L\Plat-1\Plat\Iotserver\AutodelectProtocol\Autodelectprotoctol.py:41:AutoDelect
	]
2019-01-08 13:32:44+0800 [-] info:BC9EEB51694F60AA7AA590191A79AC4F timeout
2019-01-08 13:32:44+0800 [-] info:BC9EEB51694F60AA7AA590191A79AC4F disconnected
2019-01-08 13:36:27+0800 [-] Log opened.
2019-01-08 13:36:27+0800 [-] EchoFactory starting on 8001
2019-01-08 13:36:27+0800 [-] Starting factory <__main__.EchoFactory object at 0x0475CAF0>
2019-01-08 13:36:27+0800 [-] Listening....
2019-01-08 13:36:27+0800 [-] 
2019-01-08 13:36:36+0800 [-] BC9EEB51694F60AA7AA590191A79AC4F
2019-01-08 13:36:36+0800 [-] "error:'tuple' object has no attribute 'remove'"
2019-01-08 13:36:36+0800 [-] "error:'NoneType' object is not iterable"
2019-01-08 13:36:36+0800 [-] {'model_name': '', 'data_type': {}, 'typemappointname': {}}
2019-01-08 13:36:36+0800 [-] Unhandled error in Deferred:
2019-01-08 13:36:36+0800 [-] Unhandled Error
	Traceback (most recent call last):
	  File "C:\Python\Python36-32\lib\site-packages\twisted\internet\base.py", line 1252, in mainLoop
	    self.runUntilCurrent()
	  File "C:\Python\Python36-32\lib\site-packages\twisted\internet\base.py", line 851, in runUntilCurrent
	    f(*a, **kw)
	  File "C:\Python\Python36-32\lib\site-packages\twisted\internet\defer.py", line 500, in errback
	    self._startRunCallbacks(fail)
	  File "C:\Python\Python36-32\lib\site-packages\twisted\internet\defer.py", line 567, in _startRunCallbacks
	    self._runCallbacks()
	--- <exception caught here> ---
	  File "C:\Python\Python36-32\lib\site-packages\twisted\internet\defer.py", line 653, in _runCallbacks
	    current.result = callback(current.result, *args, **kw)
	  File "E:\Python-L\Plat-1\Plat\Iotserver\server.py", line 196, in get_model_struct
	    defer_instancs = AutoDelect(self.model_struct,datastr,sqlconnect)
	  File "E:\Python-L\Plat-1\Plat\Iotserver\AutodelectProtocol\Autodelectprotoctol.py", line 31, in AutoDelect
	    typedict = model_struct['data_type'][datastream[0:2]]
	builtins.KeyError: 'A1'
	
2019-01-08 13:37:20+0800 [-] Log opened.
2019-01-08 13:37:20+0800 [-] EchoFactory starting on 8001
2019-01-08 13:37:20+0800 [-] Starting factory <__main__.EchoFactory object at 0x03D1DAF0>
2019-01-08 13:37:20+0800 [-] Listening....
2019-01-08 13:37:20+0800 [-] 
2019-01-08 13:37:30+0800 [-] BC9EEB51694F60AA7AA590191A79AC4F
2019-01-08 13:37:31+0800 [-] {'model_name': '', 'data_type': {}, 'typemappointname': {}}
2019-01-08 13:37:31+0800 [-] [(('04', 'UInt', 'temp_1'), ('03', 'Float', 'current_1'))]
2019-01-08 13:37:31+0800 [-] {'model_name': '', 'data_type': {}, 'typemappointname': {}}
2019-01-08 13:37:31+0800 [-] Unhandled error in Deferred:
2019-01-08 13:37:31+0800 [-] Unhandled Error
	Traceback (most recent call last):
	  File "C:\Python\Python36-32\lib\site-packages\twisted\internet\base.py", line 1252, in mainLoop
	    self.runUntilCurrent()
	  File "C:\Python\Python36-32\lib\site-packages\twisted\internet\base.py", line 851, in runUntilCurrent
	    f(*a, **kw)
	  File "C:\Python\Python36-32\lib\site-packages\twisted\internet\defer.py", line 459, in callback
	    self._startRunCallbacks(result)
	  File "C:\Python\Python36-32\lib\site-packages\twisted\internet\defer.py", line 567, in _startRunCallbacks
	    self._runCallbacks()
	--- <exception caught here> ---
	  File "C:\Python\Python36-32\lib\site-packages\twisted\internet\defer.py", line 653, in _runCallbacks
	    current.result = callback(current.result, *args, **kw)
	  File "E:\Python-L\Plat-1\Plat\Iotserver\server.py", line 196, in get_model_struct
	    defer_instancs = AutoDelect(self.model_struct,datastr,sqlconnect)
	  File "E:\Python-L\Plat-1\Plat\Iotserver\AutodelectProtocol\Autodelectprotoctol.py", line 31, in AutoDelect
	    typedict = model_struct['data_type'][datastream[0:2]]
	builtins.KeyError: 'A1'
	
2019-01-08 13:38:31+0800 [-] Log opened.
2019-01-08 13:38:31+0800 [-] EchoFactory starting on 8001
2019-01-08 13:38:31+0800 [-] Starting factory <__main__.EchoFactory object at 0x03B0CAF0>
2019-01-08 13:38:31+0800 [-] Listening....
2019-01-08 13:38:31+0800 [-] 
2019-01-08 13:38:35+0800 [-] BC9EEB51694F60AA7AA590191A79AC4F
2019-01-08 13:38:35+0800 [-] ((None, 'A1', 7), ('khb_product_1', 'A1', 8))
2019-01-08 13:38:35+0800 [-] {'model_name': 'khb_product_1', 'data_type': {'A1': ''}, 'typemappointname': {}}
2019-01-08 13:38:35+0800 [-] [(('01', 'Float', '电流_1'),), (('04', 'UInt', 'temp_1'), ('03', 'Float', 'current_1'))]
2019-01-08 13:38:35+0800 [-] {'model_name': 'khb_product_1', 'data_type': {'A1': {'01': 'Float'}}, 'typemappointname': {'A1': {'01': '电流_1'}}}
2019-01-08 13:38:35+0800 [-] 0304BF9C28F604040000000A
2019-01-08 13:38:35+0800 [-] AutoDelect error:[Failure instance: Traceback: <class 'KeyError'>: '03'
	C:\Python\Python36-32\lib\site-packages\twisted\internet\defer.py:567:_startRunCallbacks
	C:\Python\Python36-32\lib\site-packages\twisted\internet\defer.py:653:_runCallbacks
	E:\Python-L\Plat-1\Plat\Iotserver\server.py:196:get_model_struct
	E:\Python-L\Plat-1\Plat\Iotserver\AutodelectProtocol\Autodelectprotoctol.py:47:AutoDelect
	--- <exception caught here> ---
	E:\Python-L\Plat-1\Plat\Iotserver\AutodelectProtocol\Autodelectprotoctol.py:41:AutoDelect
	]
2019-01-08 13:40:31+0800 [-] Log opened.
2019-01-08 13:40:31+0800 [-] EchoFactory starting on 8001
2019-01-08 13:40:31+0800 [-] Starting factory <__main__.EchoFactory object at 0x042ACAF0>
2019-01-08 13:40:31+0800 [-] Listening....
2019-01-08 13:40:31+0800 [-] 
2019-01-08 13:40:34+0800 [-] BC9EEB51694F60AA7AA590191A79AC4F
2019-01-08 13:40:34+0800 [-] [(None, 'A1', 7), ('khb_product_1', 'A1', 8)]
2019-01-08 13:40:34+0800 [-] "error:'tuple' object cannot be interpreted as an integer"
2019-01-08 13:40:34+0800 [-] "error:'NoneType' object is not iterable"
2019-01-08 13:40:34+0800 [-] {'model_name': '', 'data_type': {}, 'typemappointname': {}}
2019-01-08 13:40:34+0800 [-] Unhandled error in Deferred:
2019-01-08 13:40:34+0800 [-] Unhandled Error
	Traceback (most recent call last):
	  File "C:\Python\Python36-32\lib\site-packages\twisted\internet\base.py", line 1252, in mainLoop
	    self.runUntilCurrent()
	  File "C:\Python\Python36-32\lib\site-packages\twisted\internet\base.py", line 851, in runUntilCurrent
	    f(*a, **kw)
	  File "C:\Python\Python36-32\lib\site-packages\twisted\internet\defer.py", line 500, in errback
	    self._startRunCallbacks(fail)
	  File "C:\Python\Python36-32\lib\site-packages\twisted\internet\defer.py", line 567, in _startRunCallbacks
	    self._runCallbacks()
	--- <exception caught here> ---
	  File "C:\Python\Python36-32\lib\site-packages\twisted\internet\defer.py", line 653, in _runCallbacks
	    current.result = callback(current.result, *args, **kw)
	  File "E:\Python-L\Plat-1\Plat\Iotserver\server.py", line 198, in get_model_struct
	    defer_instancs = AutoDelect(self.model_struct,datastr,sqlconnect)
	  File "E:\Python-L\Plat-1\Plat\Iotserver\AutodelectProtocol\Autodelectprotoctol.py", line 31, in AutoDelect
	    typedict = model_struct['data_type'][datastream[0:2]]
	builtins.KeyError: 'A1'
	
2019-01-08 13:42:34+0800 [-] info:BC9EEB51694F60AA7AA590191A79AC4F timeout
2019-01-08 13:42:34+0800 [-] info:BC9EEB51694F60AA7AA590191A79AC4F disconnected
2019-01-08 13:45:04+0800 [-] Log opened.
2019-01-08 13:45:04+0800 [-] EchoFactory starting on 8001
2019-01-08 13:45:04+0800 [-] Starting factory <__main__.EchoFactory object at 0x0496CAF0>
2019-01-08 13:45:04+0800 [-] Listening....
2019-01-08 13:45:04+0800 [-] 
2019-01-08 13:45:10+0800 [-] BC9EEB51694F60AA7AA590191A79AC4F
2019-01-08 13:45:12+0800 [-] [(None, 'A1', 7), ('khb_product_1', 'A1', 8)]
2019-01-08 13:45:12+0800 [-] [('khb_product_1', 'A1', 8)]
2019-01-08 13:45:12+0800 [-] {'model_name': '', 'data_type': {}, 'typemappointname': {}}
2019-01-08 13:45:12+0800 [-] [(('04', 'UInt', 'temp_1'), ('03', 'Float', 'current_1'))]
2019-01-08 13:45:12+0800 [-] {'model_name': '', 'data_type': {}, 'typemappointname': {}}
2019-01-08 13:45:12+0800 [-] Unhandled error in Deferred:
2019-01-08 13:45:12+0800 [-] Unhandled Error
	Traceback (most recent call last):
	  File "C:\Python\Python36-32\lib\site-packages\twisted\internet\base.py", line 1252, in mainLoop
	    self.runUntilCurrent()
	  File "C:\Python\Python36-32\lib\site-packages\twisted\internet\base.py", line 851, in runUntilCurrent
	    f(*a, **kw)
	  File "C:\Python\Python36-32\lib\site-packages\twisted\internet\defer.py", line 459, in callback
	    self._startRunCallbacks(result)
	  File "C:\Python\Python36-32\lib\site-packages\twisted\internet\defer.py", line 567, in _startRunCallbacks
	    self._runCallbacks()
	--- <exception caught here> ---
	  File "C:\Python\Python36-32\lib\site-packages\twisted\internet\defer.py", line 653, in _runCallbacks
	    current.result = callback(current.result, *args, **kw)
	  File "E:\Python-L\Plat-1\Plat\Iotserver\server.py", line 198, in get_model_struct
	    defer_instancs = AutoDelect(self.model_struct,datastr,sqlconnect)
	  File "E:\Python-L\Plat-1\Plat\Iotserver\AutodelectProtocol\Autodelectprotoctol.py", line 31, in AutoDelect
	    typedict = model_struct['data_type'][datastream[0:2]]
	builtins.KeyError: 'A1'
	
2019-01-08 13:47:10+0800 [-] info:BC9EEB51694F60AA7AA590191A79AC4F timeout
2019-01-08 13:47:10+0800 [-] info:BC9EEB51694F60AA7AA590191A79AC4F disconnected
2019-01-08 13:57:40+0800 [-] Log opened.
2019-01-08 13:57:40+0800 [-] EchoFactory starting on 8001
2019-01-08 13:57:40+0800 [-] Starting factory <__main__.EchoFactory object at 0x03F6CAF0>
2019-01-08 13:57:40+0800 [-] Listening....
2019-01-08 13:57:40+0800 [-] 
2019-01-08 13:57:52+0800 [-] BC9EEB51694F60AA7AA590191A79AC4F
2019-01-08 13:57:52+0800 [-] [(None, 'A1', 7), ('khb_product_1', 'A1', 8)]
2019-01-08 13:57:52+0800 [-] [('khb_product_1', 'A1', 8)]
2019-01-08 13:57:52+0800 [-] {'model_name': '', 'data_type': {}, 'typemappointname': {}}
2019-01-08 13:57:52+0800 [-] [(('04', 'UInt', 'temp_1'), ('03', 'Float', 'current_1'))]
2019-01-08 13:57:52+0800 [-] {'model_name': '', 'data_type': {}, 'typemappointname': {}}
2019-01-08 13:57:52+0800 [-] Unhandled error in Deferred:
2019-01-08 13:57:52+0800 [-] Unhandled Error
	Traceback (most recent call last):
	  File "C:\Python\Python36-32\lib\site-packages\twisted\internet\base.py", line 1252, in mainLoop
	    self.runUntilCurrent()
	  File "C:\Python\Python36-32\lib\site-packages\twisted\internet\base.py", line 851, in runUntilCurrent
	    f(*a, **kw)
	  File "C:\Python\Python36-32\lib\site-packages\twisted\internet\defer.py", line 459, in callback
	    self._startRunCallbacks(result)
	  File "C:\Python\Python36-32\lib\site-packages\twisted\internet\defer.py", line 567, in _startRunCallbacks
	    self._runCallbacks()
	--- <exception caught here> ---
	  File "C:\Python\Python36-32\lib\site-packages\twisted\internet\defer.py", line 653, in _runCallbacks
	    current.result = callback(current.result, *args, **kw)
	  File "E:\Python-L\Plat-1\Plat\Iotserver\server.py", line 199, in get_model_struct
	    defer_instancs = AutoDelect(self.model_struct,datastr,sqlconnect)
	  File "E:\Python-L\Plat-1\Plat\Iotserver\AutodelectProtocol\Autodelectprotoctol.py", line 31, in AutoDelect
	    typedict = model_struct['data_type'][datastream[0:2]]
	builtins.KeyError: 'A1'
	
2019-01-08 13:58:39+0800 [-] Log opened.
2019-01-08 13:58:39+0800 [-] EchoFactory starting on 8001
2019-01-08 13:58:39+0800 [-] Starting factory <__main__.EchoFactory object at 0x0468CAF0>
2019-01-08 13:58:39+0800 [-] Listening....
2019-01-08 13:58:39+0800 [-] 
2019-01-08 13:58:46+0800 [-] BC9EEB51694F60AA7AA590191A79AC4F
2019-01-08 13:58:46+0800 [-] [(None, 'A1', 7), ('khb_product_1', 'A1', 8)]
2019-01-08 13:58:46+0800 [-] {'model_name': '', 'data_type': {}, 'typemappointname': {}}
2019-01-08 13:58:47+0800 [-] [(('04', 'UInt', 'temp_1'), ('03', 'Float', 'current_1'))]
2019-01-08 13:58:47+0800 [-] {'model_name': '', 'data_type': {}, 'typemappointname': {}}
2019-01-08 13:58:47+0800 [-] Unhandled error in Deferred:
2019-01-08 13:58:47+0800 [-] Unhandled Error
	Traceback (most recent call last):
	  File "C:\Python\Python36-32\lib\site-packages\twisted\internet\base.py", line 1252, in mainLoop
	    self.runUntilCurrent()
	  File "C:\Python\Python36-32\lib\site-packages\twisted\internet\base.py", line 851, in runUntilCurrent
	    f(*a, **kw)
	  File "C:\Python\Python36-32\lib\site-packages\twisted\internet\defer.py", line 459, in callback
	    self._startRunCallbacks(result)
	  File "C:\Python\Python36-32\lib\site-packages\twisted\internet\defer.py", line 567, in _startRunCallbacks
	    self._runCallbacks()
	--- <exception caught here> ---
	  File "C:\Python\Python36-32\lib\site-packages\twisted\internet\defer.py", line 653, in _runCallbacks
	    current.result = callback(current.result, *args, **kw)
	  File "E:\Python-L\Plat-1\Plat\Iotserver\server.py", line 198, in get_model_struct
	    defer_instancs = AutoDelect(self.model_struct,datastr,sqlconnect)
	  File "E:\Python-L\Plat-1\Plat\Iotserver\AutodelectProtocol\Autodelectprotoctol.py", line 31, in AutoDelect
	    typedict = model_struct['data_type'][datastream[0:2]]
	builtins.KeyError: 'A1'
	
2019-01-08 14:00:46+0800 [-] info:BC9EEB51694F60AA7AA590191A79AC4F timeout
2019-01-08 14:00:46+0800 [-] info:BC9EEB51694F60AA7AA590191A79AC4F disconnected
2019-01-08 14:00:56+0800 [-] Log opened.
2019-01-08 14:00:56+0800 [-] EchoFactory starting on 8001
2019-01-08 14:00:56+0800 [-] Starting factory <__main__.EchoFactory object at 0x0488DAB0>
2019-01-08 14:00:56+0800 [-] Listening....
2019-01-08 14:00:56+0800 [-] 
2019-01-08 14:01:00+0800 [-] BC9EEB51694F60AA7AA590191A79AC4F
2019-01-08 14:01:01+0800 [-] [(None, 'A1', 7), ('khb_product_1', 'A1', 8)]
2019-01-08 14:01:01+0800 [-] {'model_name': '', 'data_type': {}, 'typemappointname': {}}
2019-01-08 14:01:01+0800 [-] [(('04', 'UInt', 'temp_1'), ('03', 'Float', 'current_1'))]
2019-01-08 14:01:01+0800 [-] {'model_name': '', 'data_type': {}, 'typemappointname': {}}
2019-01-08 14:01:01+0800 [-] Unhandled error in Deferred:
2019-01-08 14:01:01+0800 [-] Unhandled Error
	Traceback (most recent call last):
	  File "C:\Python\Python36-32\lib\site-packages\twisted\internet\base.py", line 1252, in mainLoop
	    self.runUntilCurrent()
	  File "C:\Python\Python36-32\lib\site-packages\twisted\internet\base.py", line 851, in runUntilCurrent
	    f(*a, **kw)
	  File "C:\Python\Python36-32\lib\site-packages\twisted\internet\defer.py", line 459, in callback
	    self._startRunCallbacks(result)
	  File "C:\Python\Python36-32\lib\site-packages\twisted\internet\defer.py", line 567, in _startRunCallbacks
	    self._runCallbacks()
	--- <exception caught here> ---
	  File "C:\Python\Python36-32\lib\site-packages\twisted\internet\defer.py", line 653, in _runCallbacks
	    current.result = callback(current.result, *args, **kw)
	  File "E:\Python-L\Plat-1\Plat\Iotserver\server.py", line 198, in get_model_struct
	    defer_instancs = AutoDelect(self.model_struct,datastr,sqlconnect)
	  File "E:\Python-L\Plat-1\Plat\Iotserver\AutodelectProtocol\Autodelectprotoctol.py", line 31, in AutoDelect
	    typedict = model_struct['data_type'][datastream[0:2]]
	builtins.KeyError: 'A1'
	
2019-01-08 14:03:00+0800 [-] info:BC9EEB51694F60AA7AA590191A79AC4F timeout
2019-01-08 14:03:00+0800 [-] info:BC9EEB51694F60AA7AA590191A79AC4F disconnected
2019-01-08 14:03:15+0800 [-] Log opened.
2019-01-08 14:03:15+0800 [-] EchoFactory starting on 8001
2019-01-08 14:03:15+0800 [-] Starting factory <__main__.EchoFactory object at 0x04A8DAF0>
2019-01-08 14:03:15+0800 [-] Listening....
2019-01-08 14:03:15+0800 [-] 
2019-01-08 14:03:22+0800 [-] BC9EEB51694F60AA7AA590191A79AC4F
2019-01-08 14:03:23+0800 [-] [(None, 'A1', 7), ('khb_product_1', 'A1', 8)]
2019-01-08 14:03:23+0800 [-] {'model_name': '', 'data_type': {}, 'typemappointname': {}}
2019-01-08 14:03:23+0800 [-] [(('04', 'UInt', 'temp_1'), ('03', 'Float', 'current_1'))]
2019-01-08 14:03:23+0800 [-] {'model_name': '', 'data_type': {}, 'typemappointname': {}}
2019-01-08 14:03:23+0800 [-] Unhandled error in Deferred:
2019-01-08 14:03:23+0800 [-] Unhandled Error
	Traceback (most recent call last):
	  File "C:\Python\Python36-32\lib\site-packages\twisted\internet\base.py", line 1252, in mainLoop
	    self.runUntilCurrent()
	  File "C:\Python\Python36-32\lib\site-packages\twisted\internet\base.py", line 851, in runUntilCurrent
	    f(*a, **kw)
	  File "C:\Python\Python36-32\lib\site-packages\twisted\internet\defer.py", line 459, in callback
	    self._startRunCallbacks(result)
	  File "C:\Python\Python36-32\lib\site-packages\twisted\internet\defer.py", line 567, in _startRunCallbacks
	    self._runCallbacks()
	--- <exception caught here> ---
	  File "C:\Python\Python36-32\lib\site-packages\twisted\internet\defer.py", line 653, in _runCallbacks
	    current.result = callback(current.result, *args, **kw)
	  File "E:\Python-L\Plat-1\Plat\Iotserver\server.py", line 200, in get_model_struct
	    defer_instancs = AutoDelect(self.model_struct,datastr,sqlconnect)
	  File "E:\Python-L\Plat-1\Plat\Iotserver\AutodelectProtocol\Autodelectprotoctol.py", line 31, in AutoDelect
	    typedict = model_struct['data_type'][datastream[0:2]]
	builtins.KeyError: 'A1'
	
2019-01-08 14:05:22+0800 [-] info:BC9EEB51694F60AA7AA590191A79AC4F timeout
2019-01-08 14:05:22+0800 [-] info:BC9EEB51694F60AA7AA590191A79AC4F disconnected
2019-01-08 14:12:46+0800 [-] Log opened.
2019-01-08 14:12:46+0800 [-] EchoFactory starting on 8001
2019-01-08 14:12:46+0800 [-] Starting factory <__main__.EchoFactory object at 0x0492CB10>
2019-01-08 14:12:46+0800 [-] Listening....
2019-01-08 14:12:46+0800 [-] 
2019-01-08 14:12:49+0800 [-] BC9EEB51694F60AA7AA590191A79AC4F
2019-01-08 14:12:49+0800 [-] [(None, 'A1', 7), ('khb_product_1', 'A1', 8)]
2019-01-08 14:12:49+0800 [-] 'error:list index out of range'
2019-01-08 14:12:49+0800 [-] "error:'NoneType' object is not iterable"
2019-01-08 14:12:49+0800 [-] {'model_name': '', 'data_type': {}, 'typemappointname': {}}
2019-01-08 14:12:49+0800 [-] Unhandled error in Deferred:
2019-01-08 14:12:49+0800 [-] Unhandled Error
	Traceback (most recent call last):
	  File "C:\Python\Python36-32\lib\site-packages\twisted\internet\base.py", line 1252, in mainLoop
	    self.runUntilCurrent()
	  File "C:\Python\Python36-32\lib\site-packages\twisted\internet\base.py", line 851, in runUntilCurrent
	    f(*a, **kw)
	  File "C:\Python\Python36-32\lib\site-packages\twisted\internet\defer.py", line 500, in errback
	    self._startRunCallbacks(fail)
	  File "C:\Python\Python36-32\lib\site-packages\twisted\internet\defer.py", line 567, in _startRunCallbacks
	    self._runCallbacks()
	--- <exception caught here> ---
	  File "C:\Python\Python36-32\lib\site-packages\twisted\internet\defer.py", line 653, in _runCallbacks
	    current.result = callback(current.result, *args, **kw)
	  File "E:\Python-L\Plat-1\Plat\Iotserver\server.py", line 198, in get_model_struct
	    defer_instancs = AutoDelect(self.model_struct,datastr,sqlconnect)
	  File "E:\Python-L\Plat-1\Plat\Iotserver\AutodelectProtocol\Autodelectprotoctol.py", line 31, in AutoDelect
	    typedict = model_struct['data_type'][datastream[0:2]]
	builtins.KeyError: 'A1'
	
2019-01-08 14:14:09+0800 [-] Log opened.
2019-01-08 14:14:09+0800 [-] EchoFactory starting on 8001
2019-01-08 14:14:09+0800 [-] Starting factory <__main__.EchoFactory object at 0x0418CAF0>
2019-01-08 14:14:09+0800 [-] Listening....
2019-01-08 14:14:09+0800 [-] 
2019-01-08 14:14:18+0800 [-] BC9EEB51694F60AA7AA590191A79AC4F
2019-01-08 14:14:18+0800 [-] [(None, 'A1', 7), ('khb_product_1', 'A1', 8)]
2019-01-08 14:14:18+0800 [-] 'error:list index out of range'
2019-01-08 14:14:18+0800 [-] "error:'NoneType' object is not iterable"
2019-01-08 14:14:18+0800 [-] {'model_name': '', 'data_type': {}, 'typemappointname': {}}
2019-01-08 14:14:18+0800 [-] Unhandled error in Deferred:
2019-01-08 14:14:18+0800 [-] Unhandled Error
	Traceback (most recent call last):
	  File "C:\Python\Python36-32\lib\site-packages\twisted\internet\base.py", line 1252, in mainLoop
	    self.runUntilCurrent()
	  File "C:\Python\Python36-32\lib\site-packages\twisted\internet\base.py", line 851, in runUntilCurrent
	    f(*a, **kw)
	  File "C:\Python\Python36-32\lib\site-packages\twisted\internet\defer.py", line 500, in errback
	    self._startRunCallbacks(fail)
	  File "C:\Python\Python36-32\lib\site-packages\twisted\internet\defer.py", line 567, in _startRunCallbacks
	    self._runCallbacks()
	--- <exception caught here> ---
	  File "C:\Python\Python36-32\lib\site-packages\twisted\internet\defer.py", line 653, in _runCallbacks
	    current.result = callback(current.result, *args, **kw)
	  File "E:\Python-L\Plat-1\Plat\Iotserver\server.py", line 199, in get_model_struct
	    defer_instancs = AutoDelect(self.model_struct,datastr,sqlconnect)
	  File "E:\Python-L\Plat-1\Plat\Iotserver\AutodelectProtocol\Autodelectprotoctol.py", line 31, in AutoDelect
	    typedict = model_struct['data_type'][datastream[0:2]]
	builtins.KeyError: 'A1'
	
2019-01-08 14:15:00+0800 [-] Log opened.
2019-01-08 14:15:00+0800 [-] EchoFactory starting on 8001
2019-01-08 14:15:00+0800 [-] Starting factory <__main__.EchoFactory object at 0x03B0CAF0>
2019-01-08 14:15:00+0800 [-] Listening....
2019-01-08 14:15:00+0800 [-] 
2019-01-08 14:15:03+0800 [-] BC9EEB51694F60AA7AA590191A79AC4F
2019-01-08 14:15:03+0800 [-] [(None, 'A1', 7), ('khb_product_1', 'A1', 8)]
2019-01-08 14:15:03+0800 [-] []
2019-01-08 14:15:03+0800 [-] 'error:list index out of range'
2019-01-08 14:15:03+0800 [-] "error:'NoneType' object is not iterable"
2019-01-08 14:15:03+0800 [-] {'model_name': '', 'data_type': {}, 'typemappointname': {}}
2019-01-08 14:15:03+0800 [-] Unhandled error in Deferred:
2019-01-08 14:15:03+0800 [-] Unhandled Error
	Traceback (most recent call last):
	  File "C:\Python\Python36-32\lib\site-packages\twisted\internet\base.py", line 1252, in mainLoop
	    self.runUntilCurrent()
	  File "C:\Python\Python36-32\lib\site-packages\twisted\internet\base.py", line 851, in runUntilCurrent
	    f(*a, **kw)
	  File "C:\Python\Python36-32\lib\site-packages\twisted\internet\defer.py", line 500, in errback
	    self._startRunCallbacks(fail)
	  File "C:\Python\Python36-32\lib\site-packages\twisted\internet\defer.py", line 567, in _startRunCallbacks
	    self._runCallbacks()
	--- <exception caught here> ---
	  File "C:\Python\Python36-32\lib\site-packages\twisted\internet\defer.py", line 653, in _runCallbacks
	    current.result = callback(current.result, *args, **kw)
	  File "E:\Python-L\Plat-1\Plat\Iotserver\server.py", line 198, in get_model_struct
	    defer_instancs = AutoDelect(self.model_struct,datastr,sqlconnect)
	  File "E:\Python-L\Plat-1\Plat\Iotserver\AutodelectProtocol\Autodelectprotoctol.py", line 31, in AutoDelect
	    typedict = model_struct['data_type'][datastream[0:2]]
	builtins.KeyError: 'A1'
	
2019-01-08 14:15:29+0800 [-] Log opened.
2019-01-08 14:15:29+0800 [-] EchoFactory starting on 8001
2019-01-08 14:15:29+0800 [-] Starting factory <__main__.EchoFactory object at 0x0437DAF0>
2019-01-08 14:15:29+0800 [-] Listening....
2019-01-08 14:15:29+0800 [-] 
2019-01-08 14:15:31+0800 [-] BC9EEB51694F60AA7AA590191A79AC4F
2019-01-08 14:15:31+0800 [-] [(None, 'A1', 7), ('khb_product_1', 'A1', 8)]
2019-01-08 14:15:31+0800 [-] [('khb_product_1', 'A1', 8)]
2019-01-08 14:15:31+0800 [-] {'model_name': 'A1', 'data_type': {}, 'typemappointname': {}}
2019-01-08 14:15:31+0800 [-] [(('04', 'UInt', 'temp_1'), ('03', 'Float', 'current_1'))]
2019-01-08 14:15:31+0800 [-] {'model_name': 'A1', 'data_type': {}, 'typemappointname': {}}
2019-01-08 14:15:31+0800 [-] Unhandled error in Deferred:
2019-01-08 14:15:31+0800 [-] Unhandled Error
	Traceback (most recent call last):
	  File "C:\Python\Python36-32\lib\site-packages\twisted\internet\base.py", line 1252, in mainLoop
	    self.runUntilCurrent()
	  File "C:\Python\Python36-32\lib\site-packages\twisted\internet\base.py", line 851, in runUntilCurrent
	    f(*a, **kw)
	  File "C:\Python\Python36-32\lib\site-packages\twisted\internet\defer.py", line 459, in callback
	    self._startRunCallbacks(result)
	  File "C:\Python\Python36-32\lib\site-packages\twisted\internet\defer.py", line 567, in _startRunCallbacks
	    self._runCallbacks()
	--- <exception caught here> ---
	  File "C:\Python\Python36-32\lib\site-packages\twisted\internet\defer.py", line 653, in _runCallbacks
	    current.result = callback(current.result, *args, **kw)
	  File "E:\Python-L\Plat-1\Plat\Iotserver\server.py", line 197, in get_model_struct
	    defer_instancs = AutoDelect(self.model_struct,datastr,sqlconnect)
	  File "E:\Python-L\Plat-1\Plat\Iotserver\AutodelectProtocol\Autodelectprotoctol.py", line 31, in AutoDelect
	    typedict = model_struct['data_type'][datastream[0:2]]
	builtins.KeyError: 'A1'
	
2019-01-08 14:16:55+0800 [-] Log opened.
2019-01-08 14:16:55+0800 [-] EchoFactory starting on 8001
2019-01-08 14:16:55+0800 [-] Starting factory <__main__.EchoFactory object at 0x0425CAF0>
2019-01-08 14:16:55+0800 [-] Listening....
2019-01-08 14:16:55+0800 [-] 
2019-01-08 14:16:58+0800 [-] BC9EEB51694F60AA7AA590191A79AC4F
2019-01-08 14:16:58+0800 [-] [(None, 'A1', 7), ('khb_product_1', 'A1', 8)]
2019-01-08 14:16:58+0800 [-] [('khb_product_1', 'A1', 8)]
2019-01-08 14:16:58+0800 [-] {'model_name': 'khb_product_1', 'data_type': {'A1': ''}, 'typemappointname': {}}
2019-01-08 14:16:58+0800 [-] [(('04', 'UInt', 'temp_1'), ('03', 'Float', 'current_1'))]
2019-01-08 14:16:58+0800 [-] {'model_name': 'khb_product_1', 'data_type': {'A1': {'04': 'UInt', '03': 'Float'}}, 'typemappointname': {'A1': {'04': 'temp_1', '03': 'current_1'}}}
2019-01-08 14:16:58+0800 [-] 0304BF9C28F604040000000A
2019-01-08 14:18:58+0800 [-] info:BC9EEB51694F60AA7AA590191A79AC4F timeout
2019-01-08 14:18:58+0800 [-] info:BC9EEB51694F60AA7AA590191A79AC4F disconnected
2019-01-08 14:19:48+0800 [-] Log opened.
2019-01-08 14:19:48+0800 [-] EchoFactory starting on 8001
2019-01-08 14:19:48+0800 [-] Starting factory <__main__.EchoFactory object at 0x0450EAF0>
2019-01-08 14:19:48+0800 [-] Listening....
2019-01-08 14:19:48+0800 [-] 
2019-01-08 14:22:02+0800 [-] Log opened.
2019-01-08 14:22:02+0800 [-] EchoFactory starting on 8001
2019-01-08 14:22:02+0800 [-] Starting factory <__main__.EchoFactory object at 0x03EAEAF0>
2019-01-08 14:22:02+0800 [-] Listening....
2019-01-08 14:22:02+0800 [-] 
2019-01-08 14:23:28+0800 [-] Log opened.
2019-01-08 14:23:29+0800 [-] EchoFactory starting on 8001
2019-01-08 14:23:29+0800 [-] Starting factory <__main__.EchoFactory object at 0x03B7EAF0>
2019-01-08 14:23:29+0800 [-] Listening....
2019-01-08 14:23:29+0800 [-] 
2019-01-08 14:23:32+0800 [-] BC9EEB51694F60AA7AA590191A79AC4F
2019-01-08 14:23:32+0800 [-] [(('04', 'UInt', 'temp_1'), ('03', 'Float', 'current_1'))]
2019-01-08 14:23:32+0800 [-] {'model_name': 'khb_product_1', 'data_type': {'A1': {'04': 'UInt', '03': 'Float'}}, 'typemappointname': {'A1': {'04': 'temp_1', '03': 'current_1'}}}
2019-01-08 14:23:32+0800 [-] BC9EEB51694F60AA7AA590191A79AC4F
2019-01-08 14:23:33+0800 [-] BC9EEB51694F60AA7AA590191A79AC4F
2019-01-08 14:23:34+0800 [-] BC9EEB51694F60AA7AA590191A79AC4F
2019-01-08 14:25:34+0800 [-] info:BC9EEB51694F60AA7AA590191A79AC4F timeout
2019-01-08 14:25:34+0800 [-] info:BC9EEB51694F60AA7AA590191A79AC4F disconnected
2019-01-08 14:26:11+0800 [-] Log opened.
2019-01-08 14:26:11+0800 [-] EchoFactory starting on 8001
2019-01-08 14:26:11+0800 [-] Starting factory <__main__.EchoFactory object at 0x0486CAF0>
2019-01-08 14:26:11+0800 [-] Listening....
2019-01-08 14:26:11+0800 [-] 
2019-01-08 14:26:18+0800 [-] [(('04', 'UInt', 'temp_1'), ('03', 'Float', 'current_1'))]
2019-01-08 14:26:18+0800 [-] {'model_name': 'khb_product_1', 'data_type': {'A1': {'04': 'UInt', '03': 'Float'}}, 'typemappointname': {'A1': {'04': 'temp_1', '03': 'current_1'}}}
2019-01-08 14:26:18+0800 [-] Unhandled error in Deferred:
2019-01-08 14:26:18+0800 [-] Unhandled Error
	Traceback (most recent call last):
	  File "C:\Python\Python36-32\lib\site-packages\twisted\internet\base.py", line 1252, in mainLoop
	    self.runUntilCurrent()
	  File "C:\Python\Python36-32\lib\site-packages\twisted\internet\base.py", line 851, in runUntilCurrent
	    f(*a, **kw)
	  File "C:\Python\Python36-32\lib\site-packages\twisted\internet\defer.py", line 459, in callback
	    self._startRunCallbacks(result)
	  File "C:\Python\Python36-32\lib\site-packages\twisted\internet\defer.py", line 567, in _startRunCallbacks
	    self._runCallbacks()
	--- <exception caught here> ---
	  File "C:\Python\Python36-32\lib\site-packages\twisted\internet\defer.py", line 653, in _runCallbacks
	    current.result = callback(current.result, *args, **kw)
	  File "E:\Python-L\Plat-1\Plat\Iotserver\server.py", line 195, in get_model_struct
	    defer_instancs = AutoDelect(self.model_struct,datastr,sqlconnect)
	  File "E:\Python-L\Plat-1\Plat\Iotserver\AutodelectProtocol\Autodelectprotoctol.py", line 31, in AutoDelect
	    typedict = model_struct['data_type'][datastream[0:2]]
	builtins.KeyError: 'a1'
	
2019-01-08 14:26:19+0800 [Echo,0,192.168.0.110] Unhandled Error
	Traceback (most recent call last):
	  File "C:\Python\Python36-32\lib\site-packages\twisted\python\log.py", line 103, in callWithLogger
	    return callWithContext({"system": lp}, func, *args, **kw)
	  File "C:\Python\Python36-32\lib\site-packages\twisted\python\log.py", line 86, in callWithContext
	    return context.call({ILogContext: newCtx}, func, *args, **kw)
	  File "C:\Python\Python36-32\lib\site-packages\twisted\python\context.py", line 122, in callWithContext
	    return self.currentContext().callWithContext(ctx, func, *args, **kw)
	  File "C:\Python\Python36-32\lib\site-packages\twisted\python\context.py", line 85, in callWithContext
	    return func(*args,**kw)
	--- <exception caught here> ---
	  File "C:\Python\Python36-32\lib\site-packages\twisted\internet\iocpreactor\reactor.py", line 119, in _callEventCallback
	    evt.callback(rc, numBytes, evt)
	  File "C:\Python\Python36-32\lib\site-packages\twisted\internet\iocpreactor\abstract.py", line 92, in _cbRead
	    if self._handleRead(rc, data, evt):
	  File "C:\Python\Python36-32\lib\site-packages\twisted\internet\iocpreactor\abstract.py", line 118, in _handleRead
	    return self._dispatchData()
	  File "C:\Python\Python36-32\lib\site-packages\twisted\internet\iocpreactor\abstract.py", line 75, in _dispatchData
	    self.dataReceived(self._readBuffers[full_buffers][0:remainder])
	  File "C:\Python\Python36-32\lib\site-packages\twisted\internet\iocpreactor\tcp.py", line 75, in dataReceived
	    self.protocol.dataReceived(rbuffer)
	  File "E:\Python-L\Plat-1\Plat\Iotserver\server.py", line 67, in dataReceived
	    self.datahanlder(data)
	  File "E:\Python-L\Plat-1\Plat\Iotserver\server.py", line 88, in datahanlder
	    defer_instancs = AutoDelect(self.model_struct,datastr,sqlconnect)
	  File "E:\Python-L\Plat-1\Plat\Iotserver\AutodelectProtocol\Autodelectprotoctol.py", line 31, in AutoDelect
	    typedict = model_struct['data_type'][datastream[0:2]]
	builtins.KeyError: 'a1'
	
2019-01-08 14:26:19+0800 [Echo,0,192.168.0.110] info:bc9eeb51694f60aa7aa590191a79ac4f disconnected
2019-01-08 14:36:33+0800 [Echo,1,192.168.0.110] Rollback failed
	Traceback (most recent call last):
	  File "C:\Python\Python36-32\lib\site-packages\twisted\python\threadpool.py", line 250, in inContext
	    result = inContext.theWork()
	  File "C:\Python\Python36-32\lib\site-packages\twisted\python\threadpool.py", line 266, in <lambda>
	    inContext.theWork = lambda: context.call(ctx, func, *args, **kw)
	  File "C:\Python\Python36-32\lib\site-packages\twisted\python\context.py", line 122, in callWithContext
	    return self.currentContext().callWithContext(ctx, func, *args, **kw)
	  File "C:\Python\Python36-32\lib\site-packages\twisted\python\context.py", line 85, in callWithContext
	    return func(*args,**kw)
	--- <exception caught here> ---
	  File "C:\Python\Python36-32\lib\site-packages\twisted\enterprise\adbapi.py", line 474, in _runInteraction
	    conn.rollback()
	  File "C:\Python\Python36-32\lib\site-packages\twisted\enterprise\adbapi.py", line 52, in rollback
	    self._connection.rollback()
	  File "C:\Python\Python36-32\lib\site-packages\pymysql\connections.py", line 431, in rollback
	    self._execute_command(COMMAND.COM_QUERY, "ROLLBACK")
	  File "C:\Python\Python36-32\lib\site-packages\pymysql\connections.py", line 745, in _execute_command
	    raise err.InterfaceError("(0, '')")
	pymysql.err.InterfaceError: (0, '')
	
2019-01-08 14:36:33+0800 [Echo,1,192.168.0.110] Rollback failed
	Traceback (most recent call last):
	  File "C:\Python\Python36-32\lib\site-packages\twisted\python\threadpool.py", line 250, in inContext
	    result = inContext.theWork()
	  File "C:\Python\Python36-32\lib\site-packages\twisted\python\threadpool.py", line 266, in <lambda>
	    inContext.theWork = lambda: context.call(ctx, func, *args, **kw)
	  File "C:\Python\Python36-32\lib\site-packages\twisted\python\context.py", line 122, in callWithContext
	    return self.currentContext().callWithContext(ctx, func, *args, **kw)
	  File "C:\Python\Python36-32\lib\site-packages\twisted\python\context.py", line 85, in callWithContext
	    return func(*args,**kw)
	--- <exception caught here> ---
	  File "C:\Python\Python36-32\lib\site-packages\twisted\enterprise\adbapi.py", line 474, in _runInteraction
	    conn.rollback()
	  File "C:\Python\Python36-32\lib\site-packages\twisted\enterprise\adbapi.py", line 52, in rollback
	    self._connection.rollback()
	  File "C:\Python\Python36-32\lib\site-packages\pymysql\connections.py", line 431, in rollback
	    self._execute_command(COMMAND.COM_QUERY, "ROLLBACK")
	  File "C:\Python\Python36-32\lib\site-packages\pymysql\connections.py", line 745, in _execute_command
	    raise err.InterfaceError("(0, '')")
	pymysql.err.InterfaceError: (0, '')
	
2019-01-08 14:36:33+0800 [-] 'error:(2006, "MySQL server has gone away (ConnectionResetError(10054, \'远程主机强迫关闭了一个现有的连接。\', None, 10054, None))")'
2019-01-08 14:36:33+0800 [-] Unhandled error in Deferred:
2019-01-08 14:36:33+0800 [-] Unhandled Error
	Traceback (most recent call last):
	  File "C:\Python\Python36-32\lib\site-packages\twisted\internet\base.py", line 1252, in mainLoop
	    self.runUntilCurrent()
	  File "C:\Python\Python36-32\lib\site-packages\twisted\internet\base.py", line 851, in runUntilCurrent
	    f(*a, **kw)
	  File "C:\Python\Python36-32\lib\site-packages\twisted\internet\defer.py", line 500, in errback
	    self._startRunCallbacks(fail)
	  File "C:\Python\Python36-32\lib\site-packages\twisted\internet\defer.py", line 567, in _startRunCallbacks
	    self._runCallbacks()
	--- <exception caught here> ---
	  File "C:\Python\Python36-32\lib\site-packages\twisted\internet\defer.py", line 653, in _runCallbacks
	    current.result = callback(current.result, *args, **kw)
	  File "E:\Python-L\Plat-1\Plat\Iotserver\server.py", line 145, in execute_get_type
	    _stream_type=sqlconnect.runInteraction(self.get_stream_type,model_id[0])
	builtins.TypeError: 'NoneType' object is not subscriptable
	
2019-01-08 14:36:33+0800 [-] 'error:(2006, "MySQL server has gone away (ConnectionResetError(10054, \'远程主机强迫关闭了一个现有的连接。\', None, 10054, None))")'
2019-01-08 14:36:35+0800 [Echo,1,192.168.0.110] Rollback failed
	Traceback (most recent call last):
	  File "C:\Python\Python36-32\lib\site-packages\twisted\python\threadpool.py", line 250, in inContext
	    result = inContext.theWork()
	  File "C:\Python\Python36-32\lib\site-packages\twisted\python\threadpool.py", line 266, in <lambda>
	    inContext.theWork = lambda: context.call(ctx, func, *args, **kw)
	  File "C:\Python\Python36-32\lib\site-packages\twisted\python\context.py", line 122, in callWithContext
	    return self.currentContext().callWithContext(ctx, func, *args, **kw)
	  File "C:\Python\Python36-32\lib\site-packages\twisted\python\context.py", line 85, in callWithContext
	    return func(*args,**kw)
	--- <exception caught here> ---
	  File "C:\Python\Python36-32\lib\site-packages\twisted\enterprise\adbapi.py", line 474, in _runInteraction
	    conn.rollback()
	  File "C:\Python\Python36-32\lib\site-packages\twisted\enterprise\adbapi.py", line 52, in rollback
	    self._connection.rollback()
	  File "C:\Python\Python36-32\lib\site-packages\pymysql\connections.py", line 431, in rollback
	    self._execute_command(COMMAND.COM_QUERY, "ROLLBACK")
	  File "C:\Python\Python36-32\lib\site-packages\pymysql\connections.py", line 745, in _execute_command
	    raise err.InterfaceError("(0, '')")
	pymysql.err.InterfaceError: (0, '')
	
2019-01-08 14:36:35+0800 [-] 'error:(2006, "MySQL server has gone away (ConnectionResetError(10054, \'远程主机强迫关闭了一个现有的连接。\', None, 10054, None))")'
2019-01-08 14:36:35+0800 [-] Unhandled error in Deferred:
2019-01-08 14:36:35+0800 [-] Unhandled Error
	Traceback (most recent call last):
	  File "C:\Python\Python36-32\lib\site-packages\twisted\internet\base.py", line 1252, in mainLoop
	    self.runUntilCurrent()
	  File "C:\Python\Python36-32\lib\site-packages\twisted\internet\base.py", line 851, in runUntilCurrent
	    f(*a, **kw)
	  File "C:\Python\Python36-32\lib\site-packages\twisted\internet\defer.py", line 500, in errback
	    self._startRunCallbacks(fail)
	  File "C:\Python\Python36-32\lib\site-packages\twisted\internet\defer.py", line 567, in _startRunCallbacks
	    self._runCallbacks()
	--- <exception caught here> ---
	  File "C:\Python\Python36-32\lib\site-packages\twisted\internet\defer.py", line 653, in _runCallbacks
	    current.result = callback(current.result, *args, **kw)
	  File "E:\Python-L\Plat-1\Plat\Iotserver\server.py", line 145, in execute_get_type
	    _stream_type=sqlconnect.runInteraction(self.get_stream_type,model_id[0])
	builtins.TypeError: 'NoneType' object is not subscriptable
	
2019-01-08 14:36:45+0800 [Echo,1,192.168.0.110] Rollback failed
	Traceback (most recent call last):
	  File "C:\Python\Python36-32\lib\site-packages\twisted\python\threadpool.py", line 250, in inContext
	    result = inContext.theWork()
	  File "C:\Python\Python36-32\lib\site-packages\twisted\python\threadpool.py", line 266, in <lambda>
	    inContext.theWork = lambda: context.call(ctx, func, *args, **kw)
	  File "C:\Python\Python36-32\lib\site-packages\twisted\python\context.py", line 122, in callWithContext
	    return self.currentContext().callWithContext(ctx, func, *args, **kw)
	  File "C:\Python\Python36-32\lib\site-packages\twisted\python\context.py", line 85, in callWithContext
	    return func(*args,**kw)
	--- <exception caught here> ---
	  File "C:\Python\Python36-32\lib\site-packages\twisted\enterprise\adbapi.py", line 474, in _runInteraction
	    conn.rollback()
	  File "C:\Python\Python36-32\lib\site-packages\twisted\enterprise\adbapi.py", line 52, in rollback
	    self._connection.rollback()
	  File "C:\Python\Python36-32\lib\site-packages\pymysql\connections.py", line 431, in rollback
	    self._execute_command(COMMAND.COM_QUERY, "ROLLBACK")
	  File "C:\Python\Python36-32\lib\site-packages\pymysql\connections.py", line 745, in _execute_command
	    raise err.InterfaceError("(0, '')")
	pymysql.err.InterfaceError: (0, '')
	
2019-01-08 14:36:45+0800 [-] "error:(0, '')"
2019-01-08 14:36:45+0800 [-] Unhandled error in Deferred:
2019-01-08 14:36:45+0800 [-] Unhandled Error
	Traceback (most recent call last):
	  File "C:\Python\Python36-32\lib\site-packages\twisted\internet\base.py", line 1252, in mainLoop
	    self.runUntilCurrent()
	  File "C:\Python\Python36-32\lib\site-packages\twisted\internet\base.py", line 851, in runUntilCurrent
	    f(*a, **kw)
	  File "C:\Python\Python36-32\lib\site-packages\twisted\internet\defer.py", line 500, in errback
	    self._startRunCallbacks(fail)
	  File "C:\Python\Python36-32\lib\site-packages\twisted\internet\defer.py", line 567, in _startRunCallbacks
	    self._runCallbacks()
	--- <exception caught here> ---
	  File "C:\Python\Python36-32\lib\site-packages\twisted\internet\defer.py", line 653, in _runCallbacks
	    current.result = callback(current.result, *args, **kw)
	  File "E:\Python-L\Plat-1\Plat\Iotserver\server.py", line 145, in execute_get_type
	    _stream_type=sqlconnect.runInteraction(self.get_stream_type,model_id[0])
	builtins.TypeError: 'NoneType' object is not subscriptable
	
2019-01-08 14:36:55+0800 [Echo,1,192.168.0.110] Rollback failed
	Traceback (most recent call last):
	  File "C:\Python\Python36-32\lib\site-packages\twisted\python\threadpool.py", line 250, in inContext
	    result = inContext.theWork()
	  File "C:\Python\Python36-32\lib\site-packages\twisted\python\threadpool.py", line 266, in <lambda>
	    inContext.theWork = lambda: context.call(ctx, func, *args, **kw)
	  File "C:\Python\Python36-32\lib\site-packages\twisted\python\context.py", line 122, in callWithContext
	    return self.currentContext().callWithContext(ctx, func, *args, **kw)
	  File "C:\Python\Python36-32\lib\site-packages\twisted\python\context.py", line 85, in callWithContext
	    return func(*args,**kw)
	--- <exception caught here> ---
	  File "C:\Python\Python36-32\lib\site-packages\twisted\enterprise\adbapi.py", line 474, in _runInteraction
	    conn.rollback()
	  File "C:\Python\Python36-32\lib\site-packages\twisted\enterprise\adbapi.py", line 52, in rollback
	    self._connection.rollback()
	  File "C:\Python\Python36-32\lib\site-packages\pymysql\connections.py", line 431, in rollback
	    self._execute_command(COMMAND.COM_QUERY, "ROLLBACK")
	  File "C:\Python\Python36-32\lib\site-packages\pymysql\connections.py", line 745, in _execute_command
	    raise err.InterfaceError("(0, '')")
	pymysql.err.InterfaceError: (0, '')
	
2019-01-08 14:36:55+0800 [-] "error:(0, '')"
2019-01-08 14:36:55+0800 [-] Unhandled error in Deferred:
2019-01-08 14:36:55+0800 [-] Unhandled Error
	Traceback (most recent call last):
	  File "C:\Python\Python36-32\lib\site-packages\twisted\internet\base.py", line 1252, in mainLoop
	    self.runUntilCurrent()
	  File "C:\Python\Python36-32\lib\site-packages\twisted\internet\base.py", line 851, in runUntilCurrent
	    f(*a, **kw)
	  File "C:\Python\Python36-32\lib\site-packages\twisted\internet\defer.py", line 500, in errback
	    self._startRunCallbacks(fail)
	  File "C:\Python\Python36-32\lib\site-packages\twisted\internet\defer.py", line 567, in _startRunCallbacks
	    self._runCallbacks()
	--- <exception caught here> ---
	  File "C:\Python\Python36-32\lib\site-packages\twisted\internet\defer.py", line 653, in _runCallbacks
	    current.result = callback(current.result, *args, **kw)
	  File "E:\Python-L\Plat-1\Plat\Iotserver\server.py", line 145, in execute_get_type
	    _stream_type=sqlconnect.runInteraction(self.get_stream_type,model_id[0])
	builtins.TypeError: 'NoneType' object is not subscriptable
	
2019-01-08 14:37:07+0800 [-] Log opened.
2019-01-08 14:37:07+0800 [-] EchoFactory starting on 8001
2019-01-08 14:37:07+0800 [-] Starting factory <__main__.EchoFactory object at 0x04A3CAF0>
2019-01-08 14:37:07+0800 [-] Listening....
2019-01-08 14:37:07+0800 [-] 
2019-01-08 14:37:09+0800 [-] [(('04', 'UInt', 'temp_1'), ('03', 'Float', 'current_1'))]
2019-01-08 14:37:09+0800 [-] {'model_name': 'khb_product_1', 'data_type': {'A1': {'04': 'UInt', '03': 'Float'}}, 'typemappointname': {'A1': {'04': 'temp_1', '03': 'current_1'}}}
2019-01-08 15:58:41+0800 [Echo,0,192.168.0.110] Rollback failed
	Traceback (most recent call last):
	  File "C:\Python\Python36-32\lib\site-packages\twisted\python\threadpool.py", line 250, in inContext
	    result = inContext.theWork()
	  File "C:\Python\Python36-32\lib\site-packages\twisted\python\threadpool.py", line 266, in <lambda>
	    inContext.theWork = lambda: context.call(ctx, func, *args, **kw)
	  File "C:\Python\Python36-32\lib\site-packages\twisted\python\context.py", line 122, in callWithContext
	    return self.currentContext().callWithContext(ctx, func, *args, **kw)
	  File "C:\Python\Python36-32\lib\site-packages\twisted\python\context.py", line 85, in callWithContext
	    return func(*args,**kw)
	--- <exception caught here> ---
	  File "C:\Python\Python36-32\lib\site-packages\twisted\enterprise\adbapi.py", line 474, in _runInteraction
	    conn.rollback()
	  File "C:\Python\Python36-32\lib\site-packages\twisted\enterprise\adbapi.py", line 52, in rollback
	    self._connection.rollback()
	  File "C:\Python\Python36-32\lib\site-packages\pymysql\connections.py", line 431, in rollback
	    self._execute_command(COMMAND.COM_QUERY, "ROLLBACK")
	  File "C:\Python\Python36-32\lib\site-packages\pymysql\connections.py", line 745, in _execute_command
	    raise err.InterfaceError("(0, '')")
	pymysql.err.InterfaceError: (0, '')
	
2019-01-08 15:58:41+0800 [-] Insert error:(2013, 'Lost connection to MySQL server during query ([WinError 10060] 由于连接方在一段时间后没有正确答复或连接的主机没有反应，连接尝试失败。)')
2019-01-08 15:59:01+0800 [Echo,0,192.168.0.110] Rollback failed
	Traceback (most recent call last):
	  File "C:\Python\Python36-32\lib\site-packages\twisted\python\threadpool.py", line 250, in inContext
	    result = inContext.theWork()
	  File "C:\Python\Python36-32\lib\site-packages\twisted\python\threadpool.py", line 266, in <lambda>
	    inContext.theWork = lambda: context.call(ctx, func, *args, **kw)
	  File "C:\Python\Python36-32\lib\site-packages\twisted\python\context.py", line 122, in callWithContext
	    return self.currentContext().callWithContext(ctx, func, *args, **kw)
	  File "C:\Python\Python36-32\lib\site-packages\twisted\python\context.py", line 85, in callWithContext
	    return func(*args,**kw)
	--- <exception caught here> ---
	  File "C:\Python\Python36-32\lib\site-packages\twisted\enterprise\adbapi.py", line 474, in _runInteraction
	    conn.rollback()
	  File "C:\Python\Python36-32\lib\site-packages\twisted\enterprise\adbapi.py", line 52, in rollback
	    self._connection.rollback()
	  File "C:\Python\Python36-32\lib\site-packages\pymysql\connections.py", line 431, in rollback
	    self._execute_command(COMMAND.COM_QUERY, "ROLLBACK")
	  File "C:\Python\Python36-32\lib\site-packages\pymysql\connections.py", line 745, in _execute_command
	    raise err.InterfaceError("(0, '')")
	pymysql.err.InterfaceError: (0, '')
	
2019-01-08 15:59:01+0800 [-] Insert error:(0, '')
2019-01-08 15:59:03+0800 [Echo,0,192.168.0.110] Rollback failed
	Traceback (most recent call last):
	  File "C:\Python\Python36-32\lib\site-packages\twisted\python\threadpool.py", line 250, in inContext
	    result = inContext.theWork()
	  File "C:\Python\Python36-32\lib\site-packages\twisted\python\threadpool.py", line 266, in <lambda>
	    inContext.theWork = lambda: context.call(ctx, func, *args, **kw)
	  File "C:\Python\Python36-32\lib\site-packages\twisted\python\context.py", line 122, in callWithContext
	    return self.currentContext().callWithContext(ctx, func, *args, **kw)
	  File "C:\Python\Python36-32\lib\site-packages\twisted\python\context.py", line 85, in callWithContext
	    return func(*args,**kw)
	--- <exception caught here> ---
	  File "C:\Python\Python36-32\lib\site-packages\twisted\enterprise\adbapi.py", line 474, in _runInteraction
	    conn.rollback()
	  File "C:\Python\Python36-32\lib\site-packages\twisted\enterprise\adbapi.py", line 52, in rollback
	    self._connection.rollback()
	  File "C:\Python\Python36-32\lib\site-packages\pymysql\connections.py", line 431, in rollback
	    self._execute_command(COMMAND.COM_QUERY, "ROLLBACK")
	  File "C:\Python\Python36-32\lib\site-packages\pymysql\connections.py", line 745, in _execute_command
	    raise err.InterfaceError("(0, '')")
	pymysql.err.InterfaceError: (0, '')
	
2019-01-08 15:59:03+0800 [-] Insert error:(2013, 'Lost connection to MySQL server during query ([WinError 10060] 由于连接方在一段时间后没有正确答复或连接的主机没有反应，连接尝试失败。)')
2019-01-08 15:59:11+0800 [Echo,0,192.168.0.110] Rollback failed
	Traceback (most recent call last):
	  File "C:\Python\Python36-32\lib\site-packages\twisted\python\threadpool.py", line 250, in inContext
	    result = inContext.theWork()
	  File "C:\Python\Python36-32\lib\site-packages\twisted\python\threadpool.py", line 266, in <lambda>
	    inContext.theWork = lambda: context.call(ctx, func, *args, **kw)
	  File "C:\Python\Python36-32\lib\site-packages\twisted\python\context.py", line 122, in callWithContext
	    return self.currentContext().callWithContext(ctx, func, *args, **kw)
	  File "C:\Python\Python36-32\lib\site-packages\twisted\python\context.py", line 85, in callWithContext
	    return func(*args,**kw)
	--- <exception caught here> ---
	  File "C:\Python\Python36-32\lib\site-packages\twisted\enterprise\adbapi.py", line 474, in _runInteraction
	    conn.rollback()
	  File "C:\Python\Python36-32\lib\site-packages\twisted\enterprise\adbapi.py", line 52, in rollback
	    self._connection.rollback()
	  File "C:\Python\Python36-32\lib\site-packages\pymysql\connections.py", line 431, in rollback
	    self._execute_command(COMMAND.COM_QUERY, "ROLLBACK")
	  File "C:\Python\Python36-32\lib\site-packages\pymysql\connections.py", line 745, in _execute_command
	    raise err.InterfaceError("(0, '')")
	pymysql.err.InterfaceError: (0, '')
	
2019-01-08 15:59:11+0800 [-] Insert error:(0, '')
2019-01-08 15:59:21+0800 [Echo,0,192.168.0.110] Rollback failed
	Traceback (most recent call last):
	  File "C:\Python\Python36-32\lib\site-packages\twisted\python\threadpool.py", line 250, in inContext
	    result = inContext.theWork()
	  File "C:\Python\Python36-32\lib\site-packages\twisted\python\threadpool.py", line 266, in <lambda>
	    inContext.theWork = lambda: context.call(ctx, func, *args, **kw)
	  File "C:\Python\Python36-32\lib\site-packages\twisted\python\context.py", line 122, in callWithContext
	    return self.currentContext().callWithContext(ctx, func, *args, **kw)
	  File "C:\Python\Python36-32\lib\site-packages\twisted\python\context.py", line 85, in callWithContext
	    return func(*args,**kw)
	--- <exception caught here> ---
	  File "C:\Python\Python36-32\lib\site-packages\twisted\enterprise\adbapi.py", line 474, in _runInteraction
	    conn.rollback()
	  File "C:\Python\Python36-32\lib\site-packages\twisted\enterprise\adbapi.py", line 52, in rollback
	    self._connection.rollback()
	  File "C:\Python\Python36-32\lib\site-packages\pymysql\connections.py", line 431, in rollback
	    self._execute_command(COMMAND.COM_QUERY, "ROLLBACK")
	  File "C:\Python\Python36-32\lib\site-packages\pymysql\connections.py", line 745, in _execute_command
	    raise err.InterfaceError("(0, '')")
	pymysql.err.InterfaceError: (0, '')
	
2019-01-08 15:59:21+0800 [-] Insert error:(0, '')
2019-01-08 15:59:41+0800 [Echo,0,192.168.0.110] Rollback failed
	Traceback (most recent call last):
	  File "C:\Python\Python36-32\lib\site-packages\twisted\python\threadpool.py", line 250, in inContext
	    result = inContext.theWork()
	  File "C:\Python\Python36-32\lib\site-packages\twisted\python\threadpool.py", line 266, in <lambda>
	    inContext.theWork = lambda: context.call(ctx, func, *args, **kw)
	  File "C:\Python\Python36-32\lib\site-packages\twisted\python\context.py", line 122, in callWithContext
	    return self.currentContext().callWithContext(ctx, func, *args, **kw)
	  File "C:\Python\Python36-32\lib\site-packages\twisted\python\context.py", line 85, in callWithContext
	    return func(*args,**kw)
	--- <exception caught here> ---
	  File "C:\Python\Python36-32\lib\site-packages\twisted\enterprise\adbapi.py", line 474, in _runInteraction
	    conn.rollback()
	  File "C:\Python\Python36-32\lib\site-packages\twisted\enterprise\adbapi.py", line 52, in rollback
	    self._connection.rollback()
	  File "C:\Python\Python36-32\lib\site-packages\pymysql\connections.py", line 431, in rollback
	    self._execute_command(COMMAND.COM_QUERY, "ROLLBACK")
	  File "C:\Python\Python36-32\lib\site-packages\pymysql\connections.py", line 745, in _execute_command
	    raise err.InterfaceError("(0, '')")
	pymysql.err.InterfaceError: (0, '')
	
2019-01-08 15:59:41+0800 [-] Insert error:(0, '')
2019-01-08 15:59:51+0800 [Echo,0,192.168.0.110] Rollback failed
	Traceback (most recent call last):
	  File "C:\Python\Python36-32\lib\site-packages\twisted\python\threadpool.py", line 250, in inContext
	    result = inContext.theWork()
	  File "C:\Python\Python36-32\lib\site-packages\twisted\python\threadpool.py", line 266, in <lambda>
	    inContext.theWork = lambda: context.call(ctx, func, *args, **kw)
	  File "C:\Python\Python36-32\lib\site-packages\twisted\python\context.py", line 122, in callWithContext
	    return self.currentContext().callWithContext(ctx, func, *args, **kw)
	  File "C:\Python\Python36-32\lib\site-packages\twisted\python\context.py", line 85, in callWithContext
	    return func(*args,**kw)
	--- <exception caught here> ---
	  File "C:\Python\Python36-32\lib\site-packages\twisted\enterprise\adbapi.py", line 474, in _runInteraction
	    conn.rollback()
	  File "C:\Python\Python36-32\lib\site-packages\twisted\enterprise\adbapi.py", line 52, in rollback
	    self._connection.rollback()
	  File "C:\Python\Python36-32\lib\site-packages\pymysql\connections.py", line 431, in rollback
	    self._execute_command(COMMAND.COM_QUERY, "ROLLBACK")
	  File "C:\Python\Python36-32\lib\site-packages\pymysql\connections.py", line 745, in _execute_command
	    raise err.InterfaceError("(0, '')")
	pymysql.err.InterfaceError: (0, '')
	
2019-01-08 15:59:51+0800 [-] Insert error:(0, '')
2019-01-08 16:00:11+0800 [Echo,0,192.168.0.110] Rollback failed
	Traceback (most recent call last):
	  File "C:\Python\Python36-32\lib\site-packages\twisted\python\threadpool.py", line 250, in inContext
	    result = inContext.theWork()
	  File "C:\Python\Python36-32\lib\site-packages\twisted\python\threadpool.py", line 266, in <lambda>
	    inContext.theWork = lambda: context.call(ctx, func, *args, **kw)
	  File "C:\Python\Python36-32\lib\site-packages\twisted\python\context.py", line 122, in callWithContext
	    return self.currentContext().callWithContext(ctx, func, *args, **kw)
	  File "C:\Python\Python36-32\lib\site-packages\twisted\python\context.py", line 85, in callWithContext
	    return func(*args,**kw)
	--- <exception caught here> ---
	  File "C:\Python\Python36-32\lib\site-packages\twisted\enterprise\adbapi.py", line 474, in _runInteraction
	    conn.rollback()
	  File "C:\Python\Python36-32\lib\site-packages\twisted\enterprise\adbapi.py", line 52, in rollback
	    self._connection.rollback()
	  File "C:\Python\Python36-32\lib\site-packages\pymysql\connections.py", line 431, in rollback
	    self._execute_command(COMMAND.COM_QUERY, "ROLLBACK")
	  File "C:\Python\Python36-32\lib\site-packages\pymysql\connections.py", line 745, in _execute_command
	    raise err.InterfaceError("(0, '')")
	pymysql.err.InterfaceError: (0, '')
	
2019-01-08 16:00:11+0800 [-] Insert error:(0, '')
2019-01-08 16:00:21+0800 [Echo,0,192.168.0.110] Rollback failed
	Traceback (most recent call last):
	  File "C:\Python\Python36-32\lib\site-packages\twisted\python\threadpool.py", line 250, in inContext
	    result = inContext.theWork()
	  File "C:\Python\Python36-32\lib\site-packages\twisted\python\threadpool.py", line 266, in <lambda>
	    inContext.theWork = lambda: context.call(ctx, func, *args, **kw)
	  File "C:\Python\Python36-32\lib\site-packages\twisted\python\context.py", line 122, in callWithContext
	    return self.currentContext().callWithContext(ctx, func, *args, **kw)
	  File "C:\Python\Python36-32\lib\site-packages\twisted\python\context.py", line 85, in callWithContext
	    return func(*args,**kw)
	--- <exception caught here> ---
	  File "C:\Python\Python36-32\lib\site-packages\twisted\enterprise\adbapi.py", line 474, in _runInteraction
	    conn.rollback()
	  File "C:\Python\Python36-32\lib\site-packages\twisted\enterprise\adbapi.py", line 52, in rollback
	    self._connection.rollback()
	  File "C:\Python\Python36-32\lib\site-packages\pymysql\connections.py", line 431, in rollback
	    self._execute_command(COMMAND.COM_QUERY, "ROLLBACK")
	  File "C:\Python\Python36-32\lib\site-packages\pymysql\connections.py", line 745, in _execute_command
	    raise err.InterfaceError("(0, '')")
	pymysql.err.InterfaceError: (0, '')
	
2019-01-08 16:00:21+0800 [-] Insert error:(0, '')
2019-01-08 16:00:41+0800 [Echo,0,192.168.0.110] Rollback failed
	Traceback (most recent call last):
	  File "C:\Python\Python36-32\lib\site-packages\twisted\python\threadpool.py", line 250, in inContext
	    result = inContext.theWork()
	  File "C:\Python\Python36-32\lib\site-packages\twisted\python\threadpool.py", line 266, in <lambda>
	    inContext.theWork = lambda: context.call(ctx, func, *args, **kw)
	  File "C:\Python\Python36-32\lib\site-packages\twisted\python\context.py", line 122, in callWithContext
	    return self.currentContext().callWithContext(ctx, func, *args, **kw)
	  File "C:\Python\Python36-32\lib\site-packages\twisted\python\context.py", line 85, in callWithContext
	    return func(*args,**kw)
	--- <exception caught here> ---
	  File "C:\Python\Python36-32\lib\site-packages\twisted\enterprise\adbapi.py", line 474, in _runInteraction
	    conn.rollback()
	  File "C:\Python\Python36-32\lib\site-packages\twisted\enterprise\adbapi.py", line 52, in rollback
	    self._connection.rollback()
	  File "C:\Python\Python36-32\lib\site-packages\pymysql\connections.py", line 431, in rollback
	    self._execute_command(COMMAND.COM_QUERY, "ROLLBACK")
	  File "C:\Python\Python36-32\lib\site-packages\pymysql\connections.py", line 745, in _execute_command
	    raise err.InterfaceError("(0, '')")
	pymysql.err.InterfaceError: (0, '')
	
2019-01-08 16:00:41+0800 [-] Insert error:(0, '')
2019-01-08 16:00:51+0800 [Echo,0,192.168.0.110] Rollback failed
	Traceback (most recent call last):
	  File "C:\Python\Python36-32\lib\site-packages\twisted\python\threadpool.py", line 250, in inContext
	    result = inContext.theWork()
	  File "C:\Python\Python36-32\lib\site-packages\twisted\python\threadpool.py", line 266, in <lambda>
	    inContext.theWork = lambda: context.call(ctx, func, *args, **kw)
	  File "C:\Python\Python36-32\lib\site-packages\twisted\python\context.py", line 122, in callWithContext
	    return self.currentContext().callWithContext(ctx, func, *args, **kw)
	  File "C:\Python\Python36-32\lib\site-packages\twisted\python\context.py", line 85, in callWithContext
	    return func(*args,**kw)
	--- <exception caught here> ---
	  File "C:\Python\Python36-32\lib\site-packages\twisted\enterprise\adbapi.py", line 474, in _runInteraction
	    conn.rollback()
	  File "C:\Python\Python36-32\lib\site-packages\twisted\enterprise\adbapi.py", line 52, in rollback
	    self._connection.rollback()
	  File "C:\Python\Python36-32\lib\site-packages\pymysql\connections.py", line 431, in rollback
	    self._execute_command(COMMAND.COM_QUERY, "ROLLBACK")
	  File "C:\Python\Python36-32\lib\site-packages\pymysql\connections.py", line 745, in _execute_command
	    raise err.InterfaceError("(0, '')")
	pymysql.err.InterfaceError: (0, '')
	
2019-01-08 16:00:51+0800 [-] Insert error:(0, '')
2019-01-08 16:01:11+0800 [Echo,0,192.168.0.110] Rollback failed
	Traceback (most recent call last):
	  File "C:\Python\Python36-32\lib\site-packages\twisted\python\threadpool.py", line 250, in inContext
	    result = inContext.theWork()
	  File "C:\Python\Python36-32\lib\site-packages\twisted\python\threadpool.py", line 266, in <lambda>
	    inContext.theWork = lambda: context.call(ctx, func, *args, **kw)
	  File "C:\Python\Python36-32\lib\site-packages\twisted\python\context.py", line 122, in callWithContext
	    return self.currentContext().callWithContext(ctx, func, *args, **kw)
	  File "C:\Python\Python36-32\lib\site-packages\twisted\python\context.py", line 85, in callWithContext
	    return func(*args,**kw)
	--- <exception caught here> ---
	  File "C:\Python\Python36-32\lib\site-packages\twisted\enterprise\adbapi.py", line 474, in _runInteraction
	    conn.rollback()
	  File "C:\Python\Python36-32\lib\site-packages\twisted\enterprise\adbapi.py", line 52, in rollback
	    self._connection.rollback()
	  File "C:\Python\Python36-32\lib\site-packages\pymysql\connections.py", line 431, in rollback
	    self._execute_command(COMMAND.COM_QUERY, "ROLLBACK")
	  File "C:\Python\Python36-32\lib\site-packages\pymysql\connections.py", line 745, in _execute_command
	    raise err.InterfaceError("(0, '')")
	pymysql.err.InterfaceError: (0, '')
	
2019-01-08 16:01:11+0800 [-] Insert error:(0, '')
2019-01-08 16:01:21+0800 [Echo,0,192.168.0.110] Rollback failed
	Traceback (most recent call last):
	  File "C:\Python\Python36-32\lib\site-packages\twisted\python\threadpool.py", line 250, in inContext
	    result = inContext.theWork()
	  File "C:\Python\Python36-32\lib\site-packages\twisted\python\threadpool.py", line 266, in <lambda>
	    inContext.theWork = lambda: context.call(ctx, func, *args, **kw)
	  File "C:\Python\Python36-32\lib\site-packages\twisted\python\context.py", line 122, in callWithContext
	    return self.currentContext().callWithContext(ctx, func, *args, **kw)
	  File "C:\Python\Python36-32\lib\site-packages\twisted\python\context.py", line 85, in callWithContext
	    return func(*args,**kw)
	--- <exception caught here> ---
	  File "C:\Python\Python36-32\lib\site-packages\twisted\enterprise\adbapi.py", line 474, in _runInteraction
	    conn.rollback()
	  File "C:\Python\Python36-32\lib\site-packages\twisted\enterprise\adbapi.py", line 52, in rollback
	    self._connection.rollback()
	  File "C:\Python\Python36-32\lib\site-packages\pymysql\connections.py", line 431, in rollback
	    self._execute_command(COMMAND.COM_QUERY, "ROLLBACK")
	  File "C:\Python\Python36-32\lib\site-packages\pymysql\connections.py", line 745, in _execute_command
	    raise err.InterfaceError("(0, '')")
	pymysql.err.InterfaceError: (0, '')
	
2019-01-08 16:01:21+0800 [-] Insert error:(0, '')
2019-01-08 16:01:41+0800 [Echo,0,192.168.0.110] Rollback failed
	Traceback (most recent call last):
	  File "C:\Python\Python36-32\lib\site-packages\twisted\python\threadpool.py", line 250, in inContext
	    result = inContext.theWork()
	  File "C:\Python\Python36-32\lib\site-packages\twisted\python\threadpool.py", line 266, in <lambda>
	    inContext.theWork = lambda: context.call(ctx, func, *args, **kw)
	  File "C:\Python\Python36-32\lib\site-packages\twisted\python\context.py", line 122, in callWithContext
	    return self.currentContext().callWithContext(ctx, func, *args, **kw)
	  File "C:\Python\Python36-32\lib\site-packages\twisted\python\context.py", line 85, in callWithContext
	    return func(*args,**kw)
	--- <exception caught here> ---
	  File "C:\Python\Python36-32\lib\site-packages\twisted\enterprise\adbapi.py", line 474, in _runInteraction
	    conn.rollback()
	  File "C:\Python\Python36-32\lib\site-packages\twisted\enterprise\adbapi.py", line 52, in rollback
	    self._connection.rollback()
	  File "C:\Python\Python36-32\lib\site-packages\pymysql\connections.py", line 431, in rollback
	    self._execute_command(COMMAND.COM_QUERY, "ROLLBACK")
	  File "C:\Python\Python36-32\lib\site-packages\pymysql\connections.py", line 745, in _execute_command
	    raise err.InterfaceError("(0, '')")
	pymysql.err.InterfaceError: (0, '')
	
2019-01-08 16:01:41+0800 [-] Insert error:(0, '')
2019-01-08 16:01:51+0800 [Echo,0,192.168.0.110] Rollback failed
	Traceback (most recent call last):
	  File "C:\Python\Python36-32\lib\site-packages\twisted\python\threadpool.py", line 250, in inContext
	    result = inContext.theWork()
	  File "C:\Python\Python36-32\lib\site-packages\twisted\python\threadpool.py", line 266, in <lambda>
	    inContext.theWork = lambda: context.call(ctx, func, *args, **kw)
	  File "C:\Python\Python36-32\lib\site-packages\twisted\python\context.py", line 122, in callWithContext
	    return self.currentContext().callWithContext(ctx, func, *args, **kw)
	  File "C:\Python\Python36-32\lib\site-packages\twisted\python\context.py", line 85, in callWithContext
	    return func(*args,**kw)
	--- <exception caught here> ---
	  File "C:\Python\Python36-32\lib\site-packages\twisted\enterprise\adbapi.py", line 474, in _runInteraction
	    conn.rollback()
	  File "C:\Python\Python36-32\lib\site-packages\twisted\enterprise\adbapi.py", line 52, in rollback
	    self._connection.rollback()
	  File "C:\Python\Python36-32\lib\site-packages\pymysql\connections.py", line 431, in rollback
	    self._execute_command(COMMAND.COM_QUERY, "ROLLBACK")
	  File "C:\Python\Python36-32\lib\site-packages\pymysql\connections.py", line 745, in _execute_command
	    raise err.InterfaceError("(0, '')")
	pymysql.err.InterfaceError: (0, '')
	
2019-01-08 16:01:51+0800 [-] Insert error:(0, '')
2019-01-08 16:02:11+0800 [Echo,0,192.168.0.110] Rollback failed
	Traceback (most recent call last):
	  File "C:\Python\Python36-32\lib\site-packages\twisted\python\threadpool.py", line 250, in inContext
	    result = inContext.theWork()
	  File "C:\Python\Python36-32\lib\site-packages\twisted\python\threadpool.py", line 266, in <lambda>
	    inContext.theWork = lambda: context.call(ctx, func, *args, **kw)
	  File "C:\Python\Python36-32\lib\site-packages\twisted\python\context.py", line 122, in callWithContext
	    return self.currentContext().callWithContext(ctx, func, *args, **kw)
	  File "C:\Python\Python36-32\lib\site-packages\twisted\python\context.py", line 85, in callWithContext
	    return func(*args,**kw)
	--- <exception caught here> ---
	  File "C:\Python\Python36-32\lib\site-packages\twisted\enterprise\adbapi.py", line 474, in _runInteraction
	    conn.rollback()
	  File "C:\Python\Python36-32\lib\site-packages\twisted\enterprise\adbapi.py", line 52, in rollback
	    self._connection.rollback()
	  File "C:\Python\Python36-32\lib\site-packages\pymysql\connections.py", line 431, in rollback
	    self._execute_command(COMMAND.COM_QUERY, "ROLLBACK")
	  File "C:\Python\Python36-32\lib\site-packages\pymysql\connections.py", line 745, in _execute_command
	    raise err.InterfaceError("(0, '')")
	pymysql.err.InterfaceError: (0, '')
	
2019-01-08 16:02:11+0800 [-] Insert error:(0, '')
2019-01-08 16:02:21+0800 [Echo,0,192.168.0.110] Rollback failed
	Traceback (most recent call last):
	  File "C:\Python\Python36-32\lib\site-packages\twisted\python\threadpool.py", line 250, in inContext
	    result = inContext.theWork()
	  File "C:\Python\Python36-32\lib\site-packages\twisted\python\threadpool.py", line 266, in <lambda>
	    inContext.theWork = lambda: context.call(ctx, func, *args, **kw)
	  File "C:\Python\Python36-32\lib\site-packages\twisted\python\context.py", line 122, in callWithContext
	    return self.currentContext().callWithContext(ctx, func, *args, **kw)
	  File "C:\Python\Python36-32\lib\site-packages\twisted\python\context.py", line 85, in callWithContext
	    return func(*args,**kw)
	--- <exception caught here> ---
	  File "C:\Python\Python36-32\lib\site-packages\twisted\enterprise\adbapi.py", line 474, in _runInteraction
	    conn.rollback()
	  File "C:\Python\Python36-32\lib\site-packages\twisted\enterprise\adbapi.py", line 52, in rollback
	    self._connection.rollback()
	  File "C:\Python\Python36-32\lib\site-packages\pymysql\connections.py", line 431, in rollback
	    self._execute_command(COMMAND.COM_QUERY, "ROLLBACK")
	  File "C:\Python\Python36-32\lib\site-packages\pymysql\connections.py", line 745, in _execute_command
	    raise err.InterfaceError("(0, '')")
	pymysql.err.InterfaceError: (0, '')
	
2019-01-08 16:02:21+0800 [-] Insert error:(0, '')
2019-01-08 16:02:40+0800 [Echo,0,192.168.0.110] Rollback failed
	Traceback (most recent call last):
	  File "C:\Python\Python36-32\lib\site-packages\twisted\python\threadpool.py", line 250, in inContext
	    result = inContext.theWork()
	  File "C:\Python\Python36-32\lib\site-packages\twisted\python\threadpool.py", line 266, in <lambda>
	    inContext.theWork = lambda: context.call(ctx, func, *args, **kw)
	  File "C:\Python\Python36-32\lib\site-packages\twisted\python\context.py", line 122, in callWithContext
	    return self.currentContext().callWithContext(ctx, func, *args, **kw)
	  File "C:\Python\Python36-32\lib\site-packages\twisted\python\context.py", line 85, in callWithContext
	    return func(*args,**kw)
	--- <exception caught here> ---
	  File "C:\Python\Python36-32\lib\site-packages\twisted\enterprise\adbapi.py", line 474, in _runInteraction
	    conn.rollback()
	  File "C:\Python\Python36-32\lib\site-packages\twisted\enterprise\adbapi.py", line 52, in rollback
	    self._connection.rollback()
	  File "C:\Python\Python36-32\lib\site-packages\pymysql\connections.py", line 431, in rollback
	    self._execute_command(COMMAND.COM_QUERY, "ROLLBACK")
	  File "C:\Python\Python36-32\lib\site-packages\pymysql\connections.py", line 745, in _execute_command
	    raise err.InterfaceError("(0, '')")
	pymysql.err.InterfaceError: (0, '')
	
2019-01-08 16:02:40+0800 [-] Insert error:(0, '')
2019-01-08 16:02:41+0800 [Echo,0,192.168.0.110] info:BC9EEB51694F60AA7AA590191A79AC4F disconnected
2019-01-08 16:02:41+0800 [Echo,0,192.168.0.110] Rollback failed
	Traceback (most recent call last):
	  File "C:\Python\Python36-32\lib\site-packages\twisted\python\threadpool.py", line 250, in inContext
	    result = inContext.theWork()
	  File "C:\Python\Python36-32\lib\site-packages\twisted\python\threadpool.py", line 266, in <lambda>
	    inContext.theWork = lambda: context.call(ctx, func, *args, **kw)
	  File "C:\Python\Python36-32\lib\site-packages\twisted\python\context.py", line 122, in callWithContext
	    return self.currentContext().callWithContext(ctx, func, *args, **kw)
	  File "C:\Python\Python36-32\lib\site-packages\twisted\python\context.py", line 85, in callWithContext
	    return func(*args,**kw)
	--- <exception caught here> ---
	  File "C:\Python\Python36-32\lib\site-packages\twisted\enterprise\adbapi.py", line 474, in _runInteraction
	    conn.rollback()
	  File "C:\Python\Python36-32\lib\site-packages\twisted\enterprise\adbapi.py", line 52, in rollback
	    self._connection.rollback()
	  File "C:\Python\Python36-32\lib\site-packages\pymysql\connections.py", line 431, in rollback
	    self._execute_command(COMMAND.COM_QUERY, "ROLLBACK")
	  File "C:\Python\Python36-32\lib\site-packages\pymysql\connections.py", line 745, in _execute_command
	    raise err.InterfaceError("(0, '')")
	pymysql.err.InterfaceError: (0, '')
	
2019-01-08 16:02:41+0800 [-] "error:(0, '')"
