2018-12-11 09:33:07+0800 [-] Log opened.
2018-12-11 09:33:07+0800 [-] EchoFactory starting on 8002
2018-12-11 09:33:07+0800 [-] Starting factory <__main__.EchoFactory object at 0x048C1270>
2018-12-11 09:33:07+0800 [-] Listening....
2018-12-11 09:33:07+0800 [-] 
2018-12-11 09:35:45+0800 [Echo,0,192.168.0.105] error:CRC ERROR
2018-12-11 09:35:45+0800 [-] info:0102030405060708090A0B0C disconnected
	
2018-12-11 09:36:45+0800 [-] info:0102030405060708090A0B0C timeout
2018-12-11 09:50:06+0800 [-] Log opened.
2018-12-11 09:50:06+0800 [-] EchoFactory starting on 8002
2018-12-11 09:50:06+0800 [-] Starting factory <__main__.EchoFactory object at 0x042AD2B0>
2018-12-11 09:50:06+0800 [-] Listening....
2018-12-11 09:50:06+0800 [-] 
2018-12-11 09:59:37+0800 [Echo,0,192.168.0.105] error:CRC ERROR
2018-12-11 09:59:37+0800 [-] info:0102030405060708090A0B0C disconnected
	
2018-12-11 10:28:02+0800 [Echo,1,192.168.0.105] Unhandled Error
	Traceback (most recent call last):
	  File "C:\Python\Python36-32\lib\site-packages\twisted\python\log.py", line 103, in callWithLogger
	    return callWithContext({"system": lp}, func, *args, **kw)
	  File "C:\Python\Python36-32\lib\site-packages\twisted\python\log.py", line 86, in callWithContext
	    return context.call({ILogContext: newCtx}, func, *args, **kw)
	  File "C:\Python\Python36-32\lib\site-packages\twisted\python\context.py", line 122, in callWithContext
	    return self.currentContext().callWithContext(ctx, func, *args, **kw)
	  File "C:\Python\Python36-32\lib\site-packages\twisted\python\context.py", line 85, in callWithContext
	    return func(*args,**kw)
	--- <exception caught here> ---
	  File "C:\Python\Python36-32\lib\site-packages\twisted\internet\iocpreactor\reactor.py", line 119, in _callEventCallback
	    evt.callback(rc, numBytes, evt)
	  File "C:\Python\Python36-32\lib\site-packages\twisted\internet\iocpreactor\abstract.py", line 92, in _cbRead
	    if self._handleRead(rc, data, evt):
	  File "C:\Python\Python36-32\lib\site-packages\twisted\internet\iocpreactor\abstract.py", line 105, in _handleRead
	    self.readConnectionLost(failure.Failure(main.CONNECTION_DONE))
	  File "C:\Python\Python36-32\lib\site-packages\twisted\internet\iocpreactor\tcp.py", line 116, in readConnectionLost
	    self.connectionLost(reason)
	  File "C:\Python\Python36-32\lib\site-packages\twisted\internet\iocpreactor\tcp.py", line 130, in connectionLost
	    protocol.connectionLost(reason)
	  File "E:\Python-L\Plat\Iotserver\server.py", line 124, in connectionLost
	    self.hreatbeattimeout.cancel()
	  File "C:\Python\Python36-32\lib\site-packages\twisted\internet\base.py", line 97, in cancel
	    raise error.AlreadyCancelled
	twisted.internet.error.AlreadyCancelled: Tried to cancel an already-cancelled event.
	
2018-12-11 10:28:37+0800 [Echo,2,192.168.0.105] Unhandled Error
	Traceback (most recent call last):
	  File "C:\Python\Python36-32\lib\site-packages\twisted\python\log.py", line 103, in callWithLogger
	    return callWithContext({"system": lp}, func, *args, **kw)
	  File "C:\Python\Python36-32\lib\site-packages\twisted\python\log.py", line 86, in callWithContext
	    return context.call({ILogContext: newCtx}, func, *args, **kw)
	  File "C:\Python\Python36-32\lib\site-packages\twisted\python\context.py", line 122, in callWithContext
	    return self.currentContext().callWithContext(ctx, func, *args, **kw)
	  File "C:\Python\Python36-32\lib\site-packages\twisted\python\context.py", line 85, in callWithContext
	    return func(*args,**kw)
	--- <exception caught here> ---
	  File "C:\Python\Python36-32\lib\site-packages\twisted\internet\iocpreactor\reactor.py", line 119, in _callEventCallback
	    evt.callback(rc, numBytes, evt)
	  File "C:\Python\Python36-32\lib\site-packages\twisted\internet\iocpreactor\abstract.py", line 92, in _cbRead
	    if self._handleRead(rc, data, evt):
	  File "C:\Python\Python36-32\lib\site-packages\twisted\internet\iocpreactor\abstract.py", line 105, in _handleRead
	    self.readConnectionLost(failure.Failure(main.CONNECTION_DONE))
	  File "C:\Python\Python36-32\lib\site-packages\twisted\internet\iocpreactor\tcp.py", line 116, in readConnectionLost
	    self.connectionLost(reason)
	  File "C:\Python\Python36-32\lib\site-packages\twisted\internet\iocpreactor\tcp.py", line 130, in connectionLost
	    protocol.connectionLost(reason)
	  File "E:\Python-L\Plat\Iotserver\server.py", line 124, in connectionLost
	    self.hreatbeattimeout.cancel()
	  File "C:\Python\Python36-32\lib\site-packages\twisted\internet\base.py", line 97, in cancel
	    raise error.AlreadyCancelled
	twisted.internet.error.AlreadyCancelled: Tried to cancel an already-cancelled event.
	
2018-12-11 10:30:23+0800 [-] Log opened.
2018-12-11 10:30:23+0800 [-] EchoFactory starting on 8002
2018-12-11 10:30:23+0800 [-] Starting factory <__main__.EchoFactory object at 0x049AD2B0>
2018-12-11 10:30:23+0800 [-] Listening....
2018-12-11 10:30:23+0800 [-] 
2018-12-11 12:03:41+0800 [Echo,0,192.168.0.105] error:CRC ERROR
2018-12-11 12:03:41+0800 [-] info:0102030405060708090A0B0C disconnected
2018-12-11 15:45:54+0800 [Echo,1,192.168.0.105] info:0102030405060708090A0B0C disconnected
2018-12-11 16:18:25+0800 [-] Log opened.
2018-12-11 16:18:25+0800 [-] EchoFactory starting on 8001
2018-12-11 16:18:25+0800 [-] Starting factory <__main__.EchoFactory object at 0x0468E2B0>
2018-12-11 16:18:25+0800 [-] Listening....
2018-12-11 16:18:25+0800 [-] 
2018-12-11 16:20:29+0800 [-] info:0102030405060708090A0B0C timeout
2018-12-11 16:20:29+0800 [-] Unhandled Error
	Traceback (most recent call last):
	  File "E:\Python-L\Plat\Iotserver\server.py", line 313, in <module>
	    reactor.run()
	  File "C:\Python\Python36-32\lib\site-packages\twisted\internet\base.py", line 1243, in run
	    self.mainLoop()
	  File "C:\Python\Python36-32\lib\site-packages\twisted\internet\base.py", line 1252, in mainLoop
	    self.runUntilCurrent()
	--- <exception caught here> ---
	  File "C:\Python\Python36-32\lib\site-packages\twisted\internet\base.py", line 878, in runUntilCurrent
	    call.func(*call.args, **call.kw)
	  File "C:\Python\Python36-32\lib\site-packages\twisted\internet\iocpreactor\tcp.py", line 130, in connectionLost
	    protocol.connectionLost(reason)
	  File "E:\Python-L\Plat\Iotserver\server.py", line 122, in connectionLost
	    self.hreatbeattimeout.cancel()
	  File "C:\Python\Python36-32\lib\site-packages\twisted\internet\base.py", line 99, in cancel
	    raise error.AlreadyCalled
	twisted.internet.error.AlreadyCalled: Tried to cancel an already-called event.
	
2018-12-11 16:25:32+0800 [-] Log opened.
2018-12-11 16:25:32+0800 [-] EchoFactory starting on 8001
2018-12-11 16:25:32+0800 [-] Starting factory <__main__.EchoFactory object at 0x03F4D2B0>
2018-12-11 16:25:32+0800 [-] Listening....
2018-12-11 16:25:32+0800 [-] 
2018-12-11 16:26:02+0800 [Echo,0,192.168.0.105] info:0102030405060708090A0B0C disconnected
2018-12-11 16:29:05+0800 [Echo,1,192.168.0.105] error:CRC ERROR
2018-12-11 16:29:05+0800 [-] info:0102030405060708090A0B0C disconnected
